Workbook

Sheet Original
A1: TICKET # | B1: NAME | C1: TELEFONE | E1: =F1-SUM(G1:H1) -> 31050 | F1: =500*90 -> 45000 | G1: =SUM(G2:G501)*90 -> 11610 | H1: =SUM(H2:H501)*90 -> 2340 | I1: TELEFONE | J1: QTD DE NUMEROS | K1: QTD PAGOS | L1: NUMEROS ESCOLHIDOS | M1: NOMES ESCOLHIDOS | P1: 1 | Q1: 2 | R1: 3 | S1: 4 | T1: 5 | U1: 6 | V1: 7 | Z1: 1 | AA1: 2 | AB1: 3 | AC1: 4 | AD1: 5 | AE1: 6 | AF1: 7 | AV1: TICKET # | AW1: NAME | BM1: TICKET # | BN1: NAME
A2: 1 | B2: FERNANDO CUMPA | C2: 2038209096 | D2: ok | E2: =COUNTIF($C$1:C2,C2) -> 1 | F2: =C2&E2 -> 20382090961 | G2: =IF(IFERROR(FIND("pg",LOWER(B2)),0)=0,0,1) -> 0 | H2: =IF(IFERROR(FIND("(f)",LOWER(B2)),0)=0,0,1) -> 0 | I2: 2038209096 | J2: =COUNTIF(C:C,I2) -> 3 | K2: =COUNTIFS(C:C,I2,G:G,1)+COUNTIFS(C:C,I2,H:H,1) -> 0 | L2: =CONCATENATE(P2,Q2,R2,S2,T2,U2,V2,) -> 1, 268, 318 | M2: =CONCATENATE(Z2,AA2,AB2,AC2,AD2,AE2,AF2) -> FERNANDO CUMPA ,VALENTINA ,KEVIN CUMPA | N2: =J2-K2 -> 3 | P2: =IFERROR(INDEX($A$2:$A$501,MATCH($I2&P$1,$F$2:$F$501,0)),"") -> 1 | Q2: =IFERROR(", "&INDEX($A$2:$A$501,MATCH($I2&Q$1,$F$2:$F$501,0)),"") -> , 268 | R2: =IFERROR(", "&INDEX($A$2:$A$501,MATCH($I2&R$1,$F$2:$F$501,0)),"") -> , 318 | S2: =IFERROR(", "&INDEX($A$2:$A$501,MATCH($I2&S$1,$F$2:$F$501,0)),"") | T2: =IFERROR(", "&INDEX($A$2:$A$501,MATCH($I2&T$1,$F$2:$F$501,0)),"") | U2: =IFERROR(", "&INDEX($A$2:$A$501,MATCH($I2&U$1,$F$2:$F$501,0)),"") | V2: =IFERROR(", "&INDEX($A$2:$A$501,MATCH($I2&V$1,$F$2:$F$501,0)),"") | Z2: =IFERROR(INDEX($B$2:$B$501,MATCH($I2&Z$1,$F$2:$F$501,0)),"") -> FERNANDO CUMPA | AA2: =IFERROR(" ,"&INDEX($B$2:$B$501,MATCH($I2&AA$1,$F$2:$F$501,0)),"") -> ,VALENTINA | AB2: =IFERROR(" ,"&INDEX($B$2:$B$501,MATCH($I2&AB$1,$F$2:$F$501,0)),"") -> ,KEVIN CUMPA | AC2: =IFERROR(" ,"&INDEX($B$2:$B$501,MATCH($I2&AC$1,$F$2:$F$501,0)),"") | AD2: =IFERROR(" ,"&INDEX($B$2:$B$501,MATCH($I2&AD$1,$F$2:$F$501,0)),"") | AE2: =IFERROR(" ,"&INDEX($B$2:$B$501,MATCH($I2&AE$1,$F$2:$F$501,0)),"") | AF2: =IFERROR(" ,"&INDEX($B$2:$B$501,MATCH($I2&AF$1,$F$2:$F$501,0)),"") | AV2: 1 | AW2: FERNANDO CUMPA | BM2: 1 | BN2: FERNANDO CUMPA | BO2: =VLOOKUP(BM2,A:B,2,0) -> FERNANDO CUMPA | BP2: =BO2=BN2 -> TRUE
A3: 2 | B3: ALBERT pg | C3: 6178402356 | D3: ok | E3: =COUNTIF($C$1:C3,C3) -> 1 | F3: =C3&E3 -> 61784023561 | G3: =IF(IFERROR(FIND("pg",LOWER(B3)),0)=0,0,1) -> 1 | H3: =IF(IFERROR(FIND("(f)",LOWER(B3)),0)=0,0,1) -> 0 | I3: 6178402356 | J3: =COUNTIF(C:C,I3) -> 1 | K3: =COUNTIFS(C:C,I3,G:G,1)+COUNTIFS(C:C,I3,H:H,1) -> 1 | L3: =CONCATENATE(P3,Q3,R3,S3,T3,U3,V3,) -> 2 | M3: =CONCATENATE(Z3,AA3,AB3,AC3,AD3,AE3,AF3) -> ALBERT pg | N3: =J3-K3 -> 0 | P3: =IFERROR(INDEX($A$2:$A$501,MATCH($I3&P$1,$F$2:$F$501,0)),"") -> 2 | Q3: =IFERROR(", "&INDEX($A$2:$A$501,MATCH($I3&Q$1,$F$2:$F$501,0)),"") | R3: =IFERROR(", "&INDEX($A$2:$A$501,MATCH($I3&R$1,$F$2:$F$501,0)),"") | S3: =IFERROR(", "&INDEX($A$2:$A$501,MATCH($I3&S$1,$F$2:$F$501,0)),"") | T3: =IFERROR(", "&INDEX($A$2:$A$501,MATCH($I3&T$1,$F$2:$F$501,0)),"") | U3: =IFERROR(", "&INDEX($A$2:$A$501,MATCH($I3&U$1,$F$2:$F$501,0)),"") | V3: =IFERROR(", "&INDEX($A$2:$A$501,MATCH($I3&V$1,$F$2:$F$501,0)),"") | Z3: =IFERROR(INDEX($B$2:$B$501,MATCH($I3&Z$1,$F$2:$F$501,0)),"") -> ALBERT pg | AA3: =IFERROR(" ,"&INDEX($B$2:$B$501,MATCH($I3&AA$1,$F$2:$F$501,0)),"") | AB3: =IFERROR(" ,"&INDEX($B$2:$B$501,MATCH($I3&AB$1,$F$2:$F$501,0)),"") | AC3: =IFERROR(" ,"&INDEX($B$2:$B$501,MATCH($I3&AC$1,$F$2:$F$501,0)),"") | AD3: =IFERROR(" ,"&INDEX($B$2:$B$501,MATCH($I3&AD$1,$F$2:$F$501,0)),"") | AE3: =IFERROR(" ,"&INDEX($B$2:$B$501,MATCH($I3&AE$1,$F$2:$F$501,0)),"") | AF3: =IFERROR(" ,"&INDEX($B$2:$B$501,MATCH($I3&AF$1,$F$2:$F$501,0)),"") | AV3: 2 | AW3: ALBERT | BM3: 2 | BN3: ALBERT | BO3: =VLOOKUP(BM3,A:B,2,0) -> ALBERT pg | BP3: =BO3=BN3 -> FALSE
A4: 3 | B4: KAKA | C4: 2035452391 | D4: ok | E4: =COUNTIF($C$1:C4,C4) -> 1 | F4: =C4&E4 -> 20354523911 | G4: =IF(IFERROR(FIND("pg",LOWER(B4)),0)=0,0,1) -> 0 | H4: =IF(IFERROR(FIND("(f)",LOWER(B4)),0)=0,0,1) -> 0 | I4: 2035452391 | J4: =COUNTIF(C:C,I4) -> 2 | K4: =COUNTIFS(C:C,I4,G:G,1)+COUNTIFS(C:C,I4,H:H,1) -> 0 | L4: =CONCATENATE(P4,Q4,R4,S4,T4,U4,V4,) -> 3, 9 | M4: =CONCATENATE(Z4,AA4,AB4,AC4,AD4,AE4,AF4) -> KAKA ,KAKA | N4: =J4-K4 -> 2 | P4: =IFERROR(INDEX($A$2:$A$501,MATCH($I4&P$1,$F$2:$F$501,0)),"") -> 3 | Q4: =IFERROR(", "&INDEX($A$2:$A$501,MATCH($I4&Q$1,$F$2:$F$501,0)),"") -> , 9 | R4: =IFERROR(", "&INDEX($A$2:$A$501,MATCH($I4&R$1,$F$2:$F$501,0)),"") | S4: =IFERROR(", "&INDEX($A$2:$A$501,MATCH($I4&S$1,$F$2:$F$501,0)),"") | T4: =IFERROR(", "&INDEX($A$2:$A$501,MATCH($I4&T$1,$F$2:$F$501,0)),"") | U4: =IFERROR(", "&INDEX($A$2:$A$501,MATCH($I4&U$1,$F$2:$F$501,0)),"") | V4: =IFERROR(", "&INDEX($A$2:$A$501,MATCH($I4&V$1,$F$2:$F$501,0)),"") | Z4: =IFERROR(INDEX($B$2:$B$501,MATCH($I4&Z$1,$F$2:$F$501,0)),"") -> KAKA | AA4: =IFERROR(" ,"&INDEX($B$2:$B$501,MATCH($I4&AA$1,$F$2:$F$501,0)),"") -> ,KAKA | AB4: =IFERROR(" ,"&INDEX($B$2:$B$501,MATCH($I4&AB$1,$F$2:$F$501,0)),"") | AC4: =IFERROR(" ,"&INDEX($B$2:$B$501,MATCH($I4&AC$1,$F$2:$F$501,0)),"") | AD4: =IFERROR(" ,"&INDEX($B$2:$B$501,MATCH($I4&AD$1,$F$2:$F$501,0)),"") | AE4: =IFERROR(" ,"&INDEX($B$2:$B$501,MATCH($I4&AE$1,$F$2:$F$501,0)),"") | AF4: =IFERROR(" ,"&INDEX($B$2:$B$501,MATCH($I4&AF$1,$F$2:$F$501,0)),"") | AV4: 3 | AW4: KAKA | BM4: 3 | BN4: KAKA | BO4: =VLOOKUP(BM4,A:B,2,0) -> KAKA | BP4: =BO4=BN4 -> TRUE
A5: 4 | B5: TULIO pg | C5: 9144337335 | D5: ok | E5: =COUNTIF($C$1:C5,C5) -> 1 | F5: =C5&E5 -> 91443373351 | G5: =IF(IFERROR(FIND("pg",LOWER(B5)),0)=0,0,1) -> 1 | H5: =IF(IFERROR(FIND("(f)",LOWER(B5)),0)=0,0,1) -> 0 | I5: 9144337335 | J5: =COUNTIF(C:C,I5) -> 2 | K5: =COUNTIFS(C:C,I5,G:G,1)+COUNTIFS(C:C,I5,H:H,1) -> 2 | L5: =CONCATENATE(P5,Q5,R5,S5,T5,U5,V5,) -> 4, 25 | M5: =CONCATENATE(Z5,AA5,AB5,AC5,AD5,AE5,AF5) -> TULIO pg ,TULIO pg | N5: =J5-K5 -> 0 | P5: =IFERROR(INDEX($A$2:$A$501,MATCH($I5&P$1,$F$2:$F$501,0)),"") -> 4 | Q5: =IFERROR(", "&INDEX($A$2:$A$501,MATCH($I5&Q$1,$F$2:$F$501,0)),"") -> , 25 | R5: =IFERROR(", "&INDEX($A$2:$A$501,MATCH($I5&R$1,$F$2:$F$501,0)),"") | S5: =IFERROR(", "&INDEX($A$2:$A$501,MATCH($I5&S$1,$F$2:$F$501,0)),"") | T5: =IFERROR(", "&INDEX($A$2:$A$501,MATCH($I5&T$1,$F$2:$F$501,0)),"") | U5: =IFERROR(", "&INDEX($A$2:$A$501,MATCH($I5&U$1,$F$2:$F$501,0)),"") | V5: =IFERROR(", "&INDEX($A$2:$A$501,MATCH($I5&V$1,$F$2:$F$501,0)),"") | Z5: =IFERROR(INDEX($B$2:$B$501,MATCH($I5&Z$1,$F$2:$F$501,0)),"") -> TULIO pg | AA5: =IFERROR(" ,"&INDEX($B$2:$B$501,MATCH($I5&AA$1,$F$2:$F$501,0)),"") -> ,TULIO pg | AB5: =IFERROR(" ,"&INDEX($B$2:$B$501,MATCH($I5&AB$1,$F$2:$F$501,0)),"") | AC5: =IFERROR(" ,"&INDEX($B$2:$B$501,MATCH($I5&AC$1,$F$2:$F$501,0)),"") | AD5: =IFERROR(" ,"&INDEX($B$2:$B$501,MATCH($I5&AD$1,$F$2:$F$501,0)),"") | AE5: =IFERROR(" ,"&INDEX($B$2:$B$501,MATCH($I5&AE$1,$F$2:$F$501,0)),"") | AF5: =IFERROR(" ,"&INDEX($B$2:$B$501,MATCH($I5&AF$1,$F$2:$F$501,0)),"") | AV5: 4 | AW5: TULIO | BM5: 4 | BN5: TULIO pg | BO5: =VLOOKUP(BM5,A:B,2,0) -> TULIO pg | BP5: =BO5=BN5 -> TRUE
A6: 5 | B6: VAL pg | C6: 9148828385 | D6: ok | E6: =COUNTIF($C$1:C6,C6) -> 1 | F6: =C6&E6 -> 91488283851 | G6: =IF(IFERROR(FIND("pg",LOWER(B6)),0)=0,0,1) -> 1 | H6: =IF(IFERROR(FIND("(f)",LOWER(B6)),0)=0,0,1) -> 0 | I6: 9148828385 | J6: =COUNTIF(C:C,I6) -> 1 | K6: =COUNTIFS(C:C,I6,G:G,1)+COUNTIFS(C:C,I6,H:H,1) -> 1 | L6: =CONCATENATE(P6,Q6,R6,S6,T6,U6,V6,) -> 5 | M6: =CONCATENATE(Z6,AA6,AB6,AC6,AD6,AE6,AF6) -> VAL pg | N6: =J6-K6 -> 0 | P6: =IFERROR(INDEX($A$2:$A$501,MATCH($I6&P$1,$F$2:$F$501,0)),"") -> 5 | Q6: =IFERROR(", "&INDEX($A$2:$A$501,MATCH($I6&Q$1,$F$2:$F$501,0)),"") | R6: =IFERROR(", "&INDEX($A$2:$A$501,MATCH($I6&R$1,$F$2:$F$501,0)),"") | S6: =IFERROR(", "&INDEX($A$2:$A$501,MATCH($I6&S$1,$F$2:$F$501,0)),"") | T6: =IFERROR(", "&INDEX($A$2:$A$501,MATCH($I6&T$1,$F$2:$F$501,0)),"") | U6: =IFERROR(", "&INDEX($A$2:$A$501,MATCH($I6&U$1,$F$2:$F$501,0)),"") | V6: =IFERROR(", "&INDEX($A$2:$A$501,MATCH($I6&V$1,$F$2:$F$501,0)),"") | Z6: =IFERROR(INDEX($B$2:$B$501,MATCH($I6&Z$1,$F$2:$F$501,0)),"") -> VAL pg | AA6: =IFERROR(" ,"&INDEX($B$2:$B$501,MATCH($I6&AA$1,$F$2:$F$501,0)),"") | AB6: =IFERROR(" ,"&INDEX($B$2:$B$501,MATCH($I6&AB$1,$F$2:$F$501,0)),"") | AC6: =IFERROR(" ,"&INDEX($B$2:$B$501,MATCH($I6&AC$1,$F$2:$F$501,0)),"") | AD6: =IFERROR(" ,"&INDEX($B$2:$B$501,MATCH($I6&AD$1,$F$2:$F$501,0)),"") | AE6: =IFERROR(" ,"&INDEX($B$2:$B$501,MATCH($I6&AE$1,$F$2:$F$501,0)),"") | AF6: =IFERROR(" ,"&INDEX($B$2:$B$501,MATCH($I6&AF$1,$F$2:$F$501,0)),"") | AV6: 5 | AW6: VAL | BM6: 5 | BN6: VAL pg | BO6: =VLOOKUP(BM6,A:B,2,0) -> VAL pg | BP6: =BO6=BN6 -> TRUE
A7: 6 | B7: ROGERIO PLUMBER | C7: 9148376239 | D7: ok | E7: =COUNTIF($C$1:C7,C7) -> 1 | F7: =C7&E7 -> 91483762391 | G7: =IF(IFERROR(FIND("pg",LOWER(B7)),0)=0,0,1) -> 0 | H7: =IF(IFERROR(FIND("(f)",LOWER(B7)),0)=0,0,1) -> 0 | I7: 9148376239 | J7: =COUNTIF(C:C,I7) -> 2 | K7: =COUNTIFS(C:C,I7,G:G,1)+COUNTIFS(C:C,I7,H:H,1) -> 0 | L7: =CONCATENATE(P7,Q7,R7,S7,T7,U7,V7,) -> 6, 67 | M7: =CONCATENATE(Z7,AA7,AB7,AC7,AD7,AE7,AF7) -> ROGERIO PLUMBER ,ROGERIO PLUMBER | N7: =J7-K7 -> 2 | P7: =IFERROR(INDEX($A$2:$A$501,MATCH($I7&P$1,$F$2:$F$501,0)),"") -> 6 | Q7: =IFERROR(", "&INDEX($A$2:$A$501,MATCH($I7&Q$1,$F$2:$F$501,0)),"") -> , 67 | R7: =IFERROR(", "&INDEX($A$2:$A$501,MATCH($I7&R$1,$F$2:$F$501,0)),"") | S7: =IFERROR(", "&INDEX($A$2:$A$501,MATCH($I7&S$1,$F$2:$F$501,0)),"") | T7: =IFERROR(", "&INDEX($A$2:$A$501,MATCH($I7&T$1,$F$2:$F$501,0)),"") | U7: =IFERROR(", "&INDEX($A$2:$A$501,MATCH($I7&U$1,$F$2:$F$501,0)),"") | V7: =IFERROR(", "&INDEX($A$2:$A$501,MATCH($I7&V$1,$F$2:$F$501,0)),"") | Z7: =IFERROR(INDEX($B$2:$B$501,MATCH($I7&Z$1,$F$2:$F$501,0)),"") -> ROGERIO PLUMBER | AA7: =IFERROR(" ,"&INDEX($B$2:$B$501,MATCH($I7&AA$1,$F$2:$F$501,0)),"") -> ,ROGERIO PLUMBER | AB7: =IFERROR(" ,"&INDEX($B$2:$B$501,MATCH($I7&AB$1,$F$2:$F$501,0)),"") | AC7: =IFERROR(" ,"&INDEX($B$2:$B$501,MATCH($I7&AC$1,$F$2:$F$501,0)),"") | AD7: =IFERROR(" ,"&INDEX($B$2:$B$501,MATCH($I7&AD$1,$F$2:$F$501,0)),"") | AE7: =IFERROR(" ,"&INDEX($B$2:$B$501,MATCH($I7&AE$1,$F$2:$F$501,0)),"") | AF7: =IFERROR(" ,"&INDEX($B$2:$B$501,MATCH($I7&AF$1,$F$2:$F$501,0)),"") | AV7: 6 | AW7: ROGERIO PLUMBER | BM7: 6 | BN7: ROGERIO PLUMBER | BO7: =VLOOKUP(BM7,A:B,2,0) -> ROGERIO PLUMBER | BP7: =BO7=BN7 -> TRUE
A8: 7 | B8: ANDERSON JET pg | C8: 9142276261 | D8: ok | E8: =COUNTIF($C$1:C8,C8) -> 1 | F8: =C8&E8 -> 91422762611 | G8: =IF(IFERROR(FIND("pg",LOWER(B8)),0)=0,0,1) -> 1 | H8: =IF(IFERROR(FIND("(f)",LOWER(B8)),0)=0,0,1) -> 0 | I8: 9142276261 | J8: =COUNTIF(C:C,I8) -> 1 | K8: =COUNTIFS(C:C,I8,G:G,1)+COUNTIFS(C:C,I8,H:H,1) -> 1 | L8: =CONCATENATE(P8,Q8,R8,S8,T8,U8,V8,) -> 7 | M8: =CONCATENATE(Z8,AA8,AB8,AC8,AD8,AE8,AF8) -> ANDERSON JET pg | N8: =J8-K8 -> 0 | P8: =IFERROR(INDEX($A$2:$A$501,MATCH($I8&P$1,$F$2:$F$501,0)),"") -> 7 | Q8: =IFERROR(", "&INDEX($A$2:$A$501,MATCH($I8&Q$1,$F$2:$F$501,0)),"") | R8: =IFERROR(", "&INDEX($A$2:$A$501,MATCH($I8&R$1,$F$2:$F$501,0)),"") | S8: =IFERROR(", "&INDEX($A$2:$A$501,MATCH($I8&S$1,$F$2:$F$501,0)),"") | T8: =IFERROR(", "&INDEX($A$2:$A$501,MATCH($I8&T$1,$F$2:$F$501,0)),"") | U8: =IFERROR(", "&INDEX($A$2:$A$501,MATCH($I8&U$1,$F$2:$F$501,0)),"") | V8: =IFERROR(", "&INDEX($A$2:$A$501,MATCH($I8&V$1,$F$2:$F$501,0)),"") | Z8: =IFERROR(INDEX($B$2:$B$501,MATCH($I8&Z$1,$F$2:$F$501,0)),"") -> ANDERSON JET pg | AA8: =IFERROR(" ,"&INDEX($B$2:$B$501,MATCH($I8&AA$1,$F$2:$F$501,0)),"") | AB8: =IFERROR(" ,"&INDEX($B$2:$B$501,MATCH($I8&AB$1,$F$2:$F$501,0)),"") | AC8: =IFERROR(" ,"&INDEX($B$2:$B$501,MATCH($I8&AC$1,$F$2:$F$501,0)),"") | AD8: =IFERROR(" ,"&INDEX($B$2:$B$501,MATCH($I8&AD$1,$F$2:$F$501,0)),"") | AE8: =IFERROR(" ,"&INDEX($B$2:$B$501,MATCH($I8&AE$1,$F$2:$F$501,0)),"") | AF8: =IFERROR(" ,"&INDEX($B$2:$B$501,MATCH($I8&AF$1,$F$2:$F$501,0)),"") | AV8: 7 | AW8: ANDERSON JET | BM8: 7 | BN8: ANDERSON JET pg | BO8: =VLOOKUP(BM8,A:B,2,0) -> ANDERSON JET pg | BP8: =BO8=BN8 -> TRUE
A9: 8 | B9: FRANKLYN | C9: 2039817839 | D9: ok | E9: =COUNTIF($C$1:C9,C9) -> 1 | F9: =C9&E9 -> 20398178391 | G9: =IF(IFERROR(FIND("pg",LOWER(B9)),0)=0,0,1) -> 0 | H9: =IF(IFERROR(FIND("(f)",LOWER(B9)),0)=0,0,1) -> 0 | I9: 2039817839 | J9: =COUNTIF(C:C,I9) -> 6 | K9: =COUNTIFS(C:C,I9,G:G,1)+COUNTIFS(C:C,I9,H:H,1) -> 0 | L9: =CONCATENATE(P9,Q9,R9,S9,T9,U9,V9,) -> 8, 10, 15, 51, 72, 74 | M9: =CONCATENATE(Z9,AA9,AB9,AC9,AD9,AE9,AF9) -> FRANKLYN ,FRANKLY ,FRANKLY ,FRANKLY ,FRANKLYN ,FRANKLY | N9: =J9-K9 -> 6 | P9: =IFERROR(INDEX($A$2:$A$501,MATCH($I9&P$1,$F$2:$F$501,0)),"") -> 8 | Q9: =IFERROR(", "&INDEX($A$2:$A$501,MATCH($I9&Q$1,$F$2:$F$501,0)),"") -> , 10 | R9: =IFERROR(", "&INDEX($A$2:$A$501,MATCH($I9&R$1,$F$2:$F$501,0)),"") -> , 15 | S9: =IFERROR(", "&INDEX($A$2:$A$501,MATCH($I9&S$1,$F$2:$F$501,0)),"") -> , 51 | T9: =IFERROR(", "&INDEX($A$2:$A$501,MATCH($I9&T$1,$F$2:$F$501,0)),"") -> , 72 | U9: =IFERROR(", "&INDEX($A$2:$A$501,MATCH($I9&U$1,$F$2:$F$501,0)),"") -> , 74 | V9: =IFERROR(", "&INDEX($A$2:$A$501,MATCH($I9&V$1,$F$2:$F$501,0)),"") | Z9: =IFERROR(INDEX($B$2:$B$501,MATCH($I9&Z$1,$F$2:$F$501,0)),"") -> FRANKLYN | AA9: =IFERROR(" ,"&INDEX($B$2:$B$501,MATCH($I9&AA$1,$F$2:$F$501,0)),"") -> ,FRANKLY | AB9: =IFERROR(" ,"&INDEX($B$2:$B$501,MATCH($I9&AB$1,$F$2:$F$501,0)),"") -> ,FRANKLY | AC9: =IFERROR(" ,"&INDEX($B$2:$B$501,MATCH($I9&AC$1,$F$2:$F$501,0)),"") -> ,FRANKLY | AD9: =IFERROR(" ,"&INDEX($B$2:$B$501,MATCH($I9&AD$1,$F$2:$F$501,0)),"") -> ,FRANKLYN | AE9: =IFERROR(" ,"&INDEX($B$2:$B$501,MATCH($I9&AE$1,$F$2:$F$501,0)),"") -> ,FRANKLY | AF9: =IFERROR(" ,"&INDEX($B$2:$B$501,MATCH($I9&AF$1,$F$2:$F$501,0)),"") | AV9: 8 | AW9: FRANKLYN | BM9: 8 | BN9: FRANKLYN | BO9: =VLOOKUP(BM9,A:B,2,0) -> FRANKLYN | BP9: =BO9=BN9 -> TRUE
A10: 9 | B10: KAKA | C10: 2035452391 | D10: ok | E10: =COUNTIF($C$1:C10,C10) -> 2 | F10: =C10&E10 -> 20354523912 | G10: =IF(IFERROR(FIND("pg",LOWER(B10)),0)=0,0,1) -> 0 | H10: =IF(IFERROR(FIND("(f)",LOWER(B10)),0)=0,0,1) -> 0 | I10: 9145620814 | J10: =COUNTIF(C:C,I10) -> 1 | K10: =COUNTIFS(C:C,I10,G:G,1)+COUNTIFS(C:C,I10,H:H,1) -> 0 | L10: =CONCATENATE(P10,Q10,R10,S10,T10,U10,V10,) -> 11 | M10: =CONCATENATE(Z10,AA10,AB10,AC10,AD10,AE10,AF10) -> NETO | N10: =J10-K10 -> 1 | P10: =IFERROR(INDEX($A$2:$A$501,MATCH($I10&P$1,$F$2:$F$501,0)),"") -> 11 | Q10: =IFERROR(", "&INDEX($A$2:$A$501,MATCH($I10&Q$1,$F$2:$F$501,0)),"") | R10: =IFERROR(", "&INDEX($A$2:$A$501,MATCH($I10&R$1,$F$2:$F$501,0)),"") | S10: =IFERROR(", "&INDEX($A$2:$A$501,MATCH($I10&S$1,$F$2:$F$501,0)),"") | T10: =IFERROR(", "&INDEX($A$2:$A$501,MATCH($I10&T$1,$F$2:$F$501,0)),"") | U10: =IFERROR(", "&INDEX($A$2:$A$501,MATCH($I10&U$1,$F$2:$F$501,0)),"") | V10: =IFERROR(", "&INDEX($A$2:$A$501,MATCH($I10&V$1,$F$2:$F$501,0)),"") | Z10: =IFERROR(INDEX($B$2:$B$501,MATCH($I10&Z$1,$F$2:$F$501,0)),"") -> NETO | AA10: =IFERROR(" ,"&INDEX($B$2:$B$501,MATCH($I10&AA$1,$F$2:$F$501,0)),"") | AB10: =IFERROR(" ,"&INDEX($B$2:$B$501,MATCH($I10&AB$1,$F$2:$F$501,0)),"") | AC10: =IFERROR(" ,"&INDEX($B$2:$B$501,MATCH($I10&AC$1,$F$2:$F$501,0)),"") | AD10: =IFERROR(" ,"&INDEX($B$2:$B$501,MATCH($I10&AD$1,$F$2:$F$501,0)),"") | AE10: =IFERROR(" ,"&INDEX($B$2:$B$501,MATCH($I10&AE$1,$F$2:$F$501,0)),"") | AF10: =IFERROR(" ,"&INDEX($B$2:$B$501,MATCH($I10&AF$1,$F$2:$F$501,0)),"") | AV10: 9 | AW10: KAKA | BM10: 9 | BN10: KAKA | BO10: =VLOOKUP(BM10,A:B,2,0) -> KAKA | BP10: =BO10=BN10 -> TRUE
A11: 10 | B11: FRANKLY | C11: 2039817839 | D11: ok | E11: =COUNTIF($C$1:C11,C11) -> 2 | F11: =C11&E11 -> 20398178392 | G11: =IF(IFERROR(FIND("pg",LOWER(B11)),0)=0,0,1) -> 0 | H11: =IF(IFERROR(FIND("(f)",LOWER(B11)),0)=0,0,1) -> 0 | I11: 2037150399 | J11: =COUNTIF(C:C,I11) -> 2 | K11: =COUNTIFS(C:C,I11,G:G,1)+COUNTIFS(C:C,I11,H:H,1) -> 0 | L11: =CONCATENATE(P11,Q11,R11,S11,T11,U11,V11,) -> 12, 20 | M11: =CONCATENATE(Z11,AA11,AB11,AC11,AD11,AE11,AF11) -> RICARDO SANTOS ,RICARDO SANTOS | N11: =J11-K11 -> 2 | P11: =IFERROR(INDEX($A$2:$A$501,MATCH($I11&P$1,$F$2:$F$501,0)),"") -> 12 | Q11: =IFERROR(", "&INDEX($A$2:$A$501,MATCH($I11&Q$1,$F$2:$F$501,0)),"") -> , 20 | R11: =IFERROR(", "&INDEX($A$2:$A$501,MATCH($I11&R$1,$F$2:$F$501,0)),"") | S11: =IFERROR(", "&INDEX($A$2:$A$501,MATCH($I11&S$1,$F$2:$F$501,0)),"") | T11: =IFERROR(", "&INDEX($A$2:$A$501,MATCH($I11&T$1,$F$2:$F$501,0)),"") | U11: =IFERROR(", "&INDEX($A$2:$A$501,MATCH($I11&U$1,$F$2:$F$501,0)),"") | V11: =IFERROR(", "&INDEX($A$2:$A$501,MATCH($I11&V$1,$F$2:$F$501,0)),"") | Z11: =IFERROR(INDEX($B$2:$B$501,MATCH($I11&Z$1,$F$2:$F$501,0)),"") -> RICARDO SANTOS | AA11: =IFERROR(" ,"&INDEX($B$2:$B$501,MATCH($I11&AA$1,$F$2:$F$501,0)),"") -> ,RICARDO SANTOS | AB11: =IFERROR(" ,"&INDEX($B$2:$B$501,MATCH($I11&AB$1,$F$2:$F$501,0)),"") | AC11: =IFERROR(" ,"&INDEX($B$2:$B$501,MATCH($I11&AC$1,$F$2:$F$501,0)),"") | AD11: =IFERROR(" ,"&INDEX($B$2:$B$501,MATCH($I11&AD$1,$F$2:$F$501,0)),"") | AE11: =IFERROR(" ,"&INDEX($B$2:$B$501,MATCH($I11&AE$1,$F$2:$F$501,0)),"") | AF11: =IFERROR(" ,"&INDEX($B$2:$B$501,MATCH($I11&AF$1,$F$2:$F$501,0)),"") | AV11: 10 | AW11: FRANKLY | BM11: 10 | BN11: FRANKLY | BO11: =VLOOKUP(BM11,A:B,2,0) -> FRANKLY | BP11: =BO11=BN11 -> TRUE
A12: 11 | B12: NETO | C12: 9145620814 | D12: ok | E12: =COUNTIF($C$1:C12,C12) -> 1 | F12: =C12&E12 -> 91456208141 | G12: =IF(IFERROR(FIND("pg",LOWER(B12)),0)=0,0,1) -> 0 | H12: =IF(IFERROR(FIND("(f)",LOWER(B12)),0)=0,0,1) -> 0 | I12: 2039050226 | J12: =COUNTIF(C:C,I12) -> 1 | K12: =COUNTIFS(C:C,I12,G:G,1)+COUNTIFS(C:C,I12,H:H,1) -> 0 | L12: =CONCATENATE(P12,Q12,R12,S12,T12,U12,V12,) -> 13 | M12: =CONCATENATE(Z12,AA12,AB12,AC12,AD12,AE12,AF12) -> SEANIE/JULIA | N12: =J12-K12 -> 1 | P12: =IFERROR(INDEX($A$2:$A$501,MATCH($I12&P$1,$F$2:$F$501,0)),"") -> 13 | Q12: =IFERROR(", "&INDEX($A$2:$A$501,MATCH($I12&Q$1,$F$2:$F$501,0)),"") | R12: =IFERROR(", "&INDEX($A$2:$A$501,MATCH($I12&R$1,$F$2:$F$501,0)),"") | S12: =IFERROR(", "&INDEX($A$2:$A$501,MATCH($I12&S$1,$F$2:$F$501,0)),"") | T12: =IFERROR(", "&INDEX($A$2:$A$501,MATCH($I12&T$1,$F$2:$F$501,0)),"") | U12: =IFERROR(", "&INDEX($A$2:$A$501,MATCH($I12&U$1,$F$2:$F$501,0)),"") | V12: =IFERROR(", "&INDEX($A$2:$A$501,MATCH($I12&V$1,$F$2:$F$501,0)),"") | Z12: =IFERROR(INDEX($B$2:$B$501,MATCH($I12&Z$1,$F$2:$F$501,0)),"") -> SEANIE/JULIA | AA12: =IFERROR(" ,"&INDEX($B$2:$B$501,MATCH($I12&AA$1,$F$2:$F$501,0)),"") | AB12: =IFERROR(" ,"&INDEX($B$2:$B$501,MATCH($I12&AB$1,$F$2:$F$501,0)),"") | AC12: =IFERROR(" ,"&INDEX($B$2:$B$501,MATCH($I12&AC$1,$F$2:$F$501,0)),"") | AD12: =IFERROR(" ,"&INDEX($B$2:$B$501,MATCH($I12&AD$1,$F$2:$F$501,0)),"") | AE12: =IFERROR(" ,"&INDEX($B$2:$B$501,MATCH($I12&AE$1,$F$2:$F$501,0)),"") | AF12: =IFERROR(" ,"&INDEX($B$2:$B$501,MATCH($I12&AF$1,$F$2:$F$501,0)),"") | AV12: 11 | AW12: NETO | BM12: 11 | BN12: NETO | BO12: =VLOOKUP(BM12,A:B,2,0) -> NETO | BP12: =BO12=BN12 -> TRUE
A13: 12 | B13: RICARDO SANTOS | C13: 2037150399 | D13: ok | E13: =COUNTIF($C$1:C13,C13) -> 1 | F13: =C13&E13 -> 20371503991 | G13: =IF(IFERROR(FIND("pg",LOWER(B13)),0)=0,0,1) -> 0 | H13: =IF(IFERROR(FIND("(f)",LOWER(B13)),0)=0,0,1) -> 0 | I13: 2034244624 | J13: =COUNTIF(C:C,I13) -> 2 | K13: =COUNTIFS(C:C,I13,G:G,1)+COUNTIFS(C:C,I13,H:H,1) -> 0 | L13: =CONCATENATE(P13,Q13,R13,S13,T13,U13,V13,) -> 14, 17 | M13: =CONCATENATE(Z13,AA13,AB13,AC13,AD13,AE13,AF13) -> GI ,GI | N13: =J13-K13 -> 2 | P13: =IFERROR(INDEX($A$2:$A$501,MATCH($I13&P$1,$F$2:$F$501,0)),"") -> 14 | Q13: =IFERROR(", "&INDEX($A$2:$A$501,MATCH($I13&Q$1,$F$2:$F$501,0)),"") -> , 17 | R13: =IFERROR(", "&INDEX($A$2:$A$501,MATCH($I13&R$1,$F$2:$F$501,0)),"") | S13: =IFERROR(", "&INDEX($A$2:$A$501,MATCH($I13&S$1,$F$2:$F$501,0)),"") | T13: =IFERROR(", "&INDEX($A$2:$A$501,MATCH($I13&T$1,$F$2:$F$501,0)),"") | U13: =IFERROR(", "&INDEX($A$2:$A$501,MATCH($I13&U$1,$F$2:$F$501,0)),"") | V13: =IFERROR(", "&INDEX($A$2:$A$501,MATCH($I13&V$1,$F$2:$F$501,0)),"") | Z13: =IFERROR(INDEX($B$2:$B$501,MATCH($I13&Z$1,$F$2:$F$501,0)),"") -> GI | AA13: =IFERROR(" ,"&INDEX($B$2:$B$501,MATCH($I13&AA$1,$F$2:$F$501,0)),"") -> ,GI | AB13: =IFERROR(" ,"&INDEX($B$2:$B$501,MATCH($I13&AB$1,$F$2:$F$501,0)),"") | AC13: =IFERROR(" ,"&INDEX($B$2:$B$501,MATCH($I13&AC$1,$F$2:$F$501,0)),"") | AD13: =IFERROR(" ,"&INDEX($B$2:$B$501,MATCH($I13&AD$1,$F$2:$F$501,0)),"") | AE13: =IFERROR(" ,"&INDEX($B$2:$B$501,MATCH($I13&AE$1,$F$2:$F$501,0)),"") | AF13: =IFERROR(" ,"&INDEX($B$2:$B$501,MATCH($I13&AF$1,$F$2:$F$501,0)),"") | AV13: 12 | AW13: RICARDO SANTOS | BM13: 12 | BN13: RICARDO SANTOS | BO13: =VLOOKUP(BM13,A:B,2,0) -> RICARDO SANTOS | BP13: =BO13=BN13 -> TRUE
... A16: 15 | B16: FRANKLY | C16: 2039817839 | D16: ok | E16: =COUNTIF($C$1:C16,C16) -> 3 | F16: =C16&E16 -> 20398178393 | G16: =IF(IFERROR(FIND("pg",LOWER(B16)),0)=0,0,1) -> 0 | H16: =IF(IFERROR(FIND("(f)",LOWER(B16)),0)=0,0,1) -> 0 | I16: 2033490246 | J16: =COUNTIF(C:C,I16) -> 5 | K16: =COUNTIFS(C:C,I16,G:G,1)+COUNTIFS(C:C,I16,H:H,1) -> 4 | L16: =CONCATENATE(P16,Q16,R16,S16,T16,U16,V16,) -> 21, 29, 62, 191, 500 | M16: =CONCATENATE(Z16,AA16,AB16,AC16,AD16,AE16,AF16) -> SOLON pg ,SOLON pg ,EDINEI ALVES amigo solon ,SOLON pg ,SOLON pg | N16: =J16-K16 -> 1 | P16: =IFERROR(INDEX($A$2:$A$501,MATCH($I16&P$1,$F$2:$F$501,0)),"") -> 21 | Q16: =IFERROR(", "&INDEX($A$2:$A$501,MATCH($I16&Q$1,$F$2:$F$501,0)),"") -> , 29 | R16: =IFERROR(", "&INDEX($A$2:$A$501,MATCH($I16&R$1,$F$2:$F$501,0)),"") -> , 62 | S16: =IFERROR(", "&INDEX($A$2:$A$501,MATCH($I16&S$1,$F$2:$F$501,0)),"") -> , 191 | T16: =IFERROR(", "&INDEX($A$2:$A$501,MATCH($I16&T$1,$F$2:$F$501,0)),"") -> , 500 | U16: =IFERROR(", "&INDEX($A$2:$A$501,MATCH($I16&U$1,$F$2:$F$501,0)),"") | V16: =IFERROR(", "&INDEX($A$2:$A$501,MATCH($I16&V$1,$F$2:$F$501,0)),"") | Z16: =IFERROR(INDEX($B$2:$B$501,MATCH($I16&Z$1,$F$2:$F$501,0)),"") -> SOLON pg | AA16: =IFERROR(" ,"&INDEX($B$2:$B$501,MATCH($I16&AA$1,$F$2:$F$501,0)),"") -> ,SOLON pg | AB16: =IFERROR(" ,"&INDEX($B$2:$B$501,MATCH($I16&AB$1,$F$2:$F$501,0)),"") -> ,EDINEI ALVES amigo solon | AC16: =IFERROR(" ,"&INDEX($B$2:$B$501,MATCH($I16&AC$1,$F$2:$F$501,0)),"") -> ,SOLON pg | AD16: =IFERROR(" ,"&INDEX($B$2:$B$501,MATCH($I16&AD$1,$F$2:$F$501,0)),"") -> ,SOLON pg | AE16: =IFERROR(" ,"&INDEX($B$2:$B$501,MATCH($I16&AE$1,$F$2:$F$501,0)),"") | AF16: =IFERROR(" ,"&INDEX($B$2:$B$501,MATCH($I16&AF$1,$F$2:$F$501,0)),"") | AV16: 15 | AW16: FRANKLY | BM16: 15 | BN16: FRANKLY | BO16: =VLOOKUP(BM16,A:B,2,0) -> FRANKLY | BP16: =BO16=BN16 -> TRUE
A17: 16 | E17: =COUNTIF($C$1:C17,C17) -> 0 | F17: =C17&E17 -> 0 | G17: =IF(IFERROR(FIND("pg",LOWER(B17)),0)=0,0,1) -> 0 | H17: =IF(IFERROR(FIND("(f)",LOWER(B17)),0)=0,0,1) -> 0 | I17: 9144975684 | J17: =COUNTIF(C:C,I17) -> 2 | K17: =COUNTIFS(C:C,I17,G:G,1)+COUNTIFS(C:C,I17,H:H,1) -> 2 | L17: =CONCATENATE(P17,Q17,R17,S17,T17,U17,V17,) -> 22, 60 | M17: =CONCATENATE(Z17,AA17,AB17,AC17,AD17,AE17,AF17) -> BOY pg ,BOY pg | N17: =J17-K17 -> 0 | P17: =IFERROR(INDEX($A$2:$A$501,MATCH($I17&P$1,$F$2:$F$501,0)),"") -> 22 | Q17: =IFERROR(", "&INDEX($A$2:$A$501,MATCH($I17&Q$1,$F$2:$F$501,0)),"") -> , 60 | R17: =IFERROR(", "&INDEX($A$2:$A$501,MATCH($I17&R$1,$F$2:$F$501,0)),"") | S17: =IFERROR(", "&INDEX($A$2:$A$501,MATCH($I17&S$1,$F$2:$F$501,0)),"") | T17: =IFERROR(", "&INDEX($A$2:$A$501,MATCH($I17&T$1,$F$2:$F$501,0)),"") | U17: =IFERROR(", "&INDEX($A$2:$A$501,MATCH($I17&U$1,$F$2:$F$501,0)),"") | V17: =IFERROR(", "&INDEX($A$2:$A$501,MATCH($I17&V$1,$F$2:$F$501,0)),"") | Z17: =IFERROR(INDEX($B$2:$B$501,MATCH($I17&Z$1,$F$2:$F$501,0)),"") -> BOY pg | AA17: =IFERROR(" ,"&INDEX($B$2:$B$501,MATCH($I17&AA$1,$F$2:$F$501,0)),"") -> ,BOY pg | AB17: =IFERROR(" ,"&INDEX($B$2:$B$501,MATCH($I17&AB$1,$F$2:$F$501,0)),"") | AC17: =IFERROR(" ,"&INDEX($B$2:$B$501,MATCH($I17&AC$1,$F$2:$F$501,0)),"") | AD17: =IFERROR(" ,"&INDEX($B$2:$B$501,MATCH($I17&AD$1,$F$2:$F$501,0)),"") | AE17: =IFERROR(" ,"&INDEX($B$2:$B$501,MATCH($I17&AE$1,$F$2:$F$501,0)),"") | AF17: =IFERROR(" ,"&INDEX($B$2:$B$501,MATCH($I17&AF$1,$F$2:$F$501,0)),"") | AV17: 16 | BM17: 16 | BO17: =VLOOKUP(BM17,A:B,2,0) -> 0 | BP17: =BO17=BN17 -> TRUE
A18: 17 | B18: GI | C18: 2034244624 | D18: ok | E18: =COUNTIF($C$1:C18,C18) -> 2 | F18: =C18&E18 -> 20342446242 | G18: =IF(IFERROR(FIND("pg",LOWER(B18)),0)=0,0,1) -> 0 | H18: =IF(IFERROR(FIND("(f)",LOWER(B18)),0)=0,0,1) -> 0 | I18: 2039538965 | J18: =COUNTIF(C:C,I18) -> 0 | K18: =COUNTIFS(C:C,I18,G:G,1)+COUNTIFS(C:C,I18,H:H,1) -> 0 | L18: =CONCATENATE(P18,Q18,R18,S18,T18,U18,V18,) | M18: =CONCATENATE(Z18,AA18,AB18,AC18,AD18,AE18,AF18) | N18: =J18-K18 -> 0 | P18: =IFERROR(INDEX($A$2:$A$501,MATCH($I18&P$1,$F$2:$F$501,0)),"") | Q18: =IFERROR(", "&INDEX($A$2:$A$501,MATCH($I18&Q$1,$F$2:$F$501,0)),"") | R18: =IFERROR(", "&INDEX($A$2:$A$501,MATCH($I18&R$1,$F$2:$F$501,0)),"") | S18: =IFERROR(", "&INDEX($A$2:$A$501,MATCH($I18&S$1,$F$2:$F$501,0)),"") | T18: =IFERROR(", "&INDEX($A$2:$A$501,MATCH($I18&T$1,$F$2:$F$501,0)),"") | U18: =IFERROR(", "&INDEX($A$2:$A$501,MATCH($I18&U$1,$F$2:$F$501,0)),"") | V18: =IFERROR(", "&INDEX($A$2:$A$501,MATCH($I18&V$1,$F$2:$F$501,0)),"") | Z18: =IFERROR(INDEX($B$2:$B$501,MATCH($I18&Z$1,$F$2:$F$501,0)),"") | AA18: =IFERROR(" ,"&INDEX($B$2:$B$501,MATCH($I18&AA$1,$F$2:$F$501,0)),"") | AB18: =IFERROR(" ,"&INDEX($B$2:$B$501,MATCH($I18&AB$1,$F$2:$F$501,0)),"") | AC18: =IFERROR(" ,"&INDEX($B$2:$B$501,MATCH($I18&AC$1,$F$2:$F$501,0)),"") | AD18: =IFERROR(" ,"&INDEX($B$2:$B$501,MATCH($I18&AD$1,$F$2:$F$501,0)),"") | AE18: =IFERROR(" ,"&INDEX($B$2:$B$501,MATCH($I18&AE$1,$F$2:$F$501,0)),"") | AF18: =IFERROR(" ,"&INDEX($B$2:$B$501,MATCH($I18&AF$1,$F$2:$F$501,0)),"") | AV18: 17 | AW18: GI | BM18: 17 | BN18: GI | BO18: =VLOOKUP(BM18,A:B,2,0) -> GI | BP18: =BO18=BN18 -> TRUE
A19: 18 | B19: SERGIO | C19: 2038580805 | D19: ok | E19: =COUNTIF($C$1:C19,C19) -> 1 | F19: =C19&E19 -> 20385808051 | G19: =IF(IFERROR(FIND("pg",LOWER(B19)),0)=0,0,1) -> 0 | H19: =IF(IFERROR(FIND("(f)",LOWER(B19)),0)=0,0,1) -> 0 | I19: 2039943998 | J19: =COUNTIF(C:C,I19) -> 4 | K19: =COUNTIFS(C:C,I19,G:G,1)+COUNTIFS(C:C,I19,H:H,1) -> 0 | L19: =CONCATENATE(P19,Q19,R19,S19,T19,U19,V19,) -> 26, 45, 171, 226 | M19: =CONCATENATE(Z19,AA19,AB19,AC19,AD19,AE19,AF19) -> FERNANDO XARA ,FERNANDO XARA ,FERNANDO XARA ,FERNANDO XARA | N19: =J19-K19 -> 4 | P19: =IFERROR(INDEX($A$2:$A$501,MATCH($I19&P$1,$F$2:$F$501,0)),"") -> 26 | Q19: =IFERROR(", "&INDEX($A$2:$A$501,MATCH($I19&Q$1,$F$2:$F$501,0)),"") -> , 45 | R19: =IFERROR(", "&INDEX($A$2:$A$501,MATCH($I19&R$1,$F$2:$F$501,0)),"") -> , 171 | S19: =IFERROR(", "&INDEX($A$2:$A$501,MATCH($I19&S$1,$F$2:$F$501,0)),"") -> , 226 | T19: =IFERROR(", "&INDEX($A$2:$A$501,MATCH($I19&T$1,$F$2:$F$501,0)),"") | U19: =IFERROR(", "&INDEX($A$2:$A$501,MATCH($I19&U$1,$F$2:$F$501,0)),"") | V19: =IFERROR(", "&INDEX($A$2:$A$501,MATCH($I19&V$1,$F$2:$F$501,0)),"") | Z19: =IFERROR(INDEX($B$2:$B$501,MATCH($I19&Z$1,$F$2:$F$501,0)),"") -> FERNANDO XARA | AA19: =IFERROR(" ,"&INDEX($B$2:$B$501,MATCH($I19&AA$1,$F$2:$F$501,0)),"") -> ,FERNANDO XARA | AB19: =IFERROR(" ,"&INDEX($B$2:$B$501,MATCH($I19&AB$1,$F$2:$F$501,0)),"") -> ,FERNANDO XARA | AC19: =IFERROR(" ,"&INDEX($B$2:$B$501,MATCH($I19&AC$1,$F$2:$F$501,0)),"") -> ,FERNANDO XARA | AD19: =IFERROR(" ,"&INDEX($B$2:$B$501,MATCH($I19&AD$1,$F$2:$F$501,0)),"") | AE19: =IFERROR(" ,"&INDEX($B$2:$B$501,MATCH($I19&AE$1,$F$2:$F$501,0)),"") | AF19: =IFERROR(" ,"&INDEX($B$2:$B$501,MATCH($I19&AF$1,$F$2:$F$501,0)),"") | AV19: 18 | AW19: SERGIO | BM19: 18 | BN19: SERGIO | BO19: =VLOOKUP(BM19,A:B,2,0) -> SERGIO | BP19: =BO19=BN19 -> TRUE
A20: 19 | B20: GILSON pg | C20: 2032803585 | D20: ok | E20: =COUNTIF($C$1:C20,C20) -> 1 | F20: =C20&E20 -> 20328035851 | G20: =IF(IFERROR(FIND("pg",LOWER(B20)),0)=0,0,1) -> 1 | H20: =IF(IFERROR(FIND("(f)",LOWER(B20)),0)=0,0,1) -> 0 | I20: 5511997219288 | J20: =COUNTIF(C:C,I20) -> 1 | K20: =COUNTIFS(C:C,I20,G:G,1)+COUNTIFS(C:C,I20,H:H,1) -> 0 | L20: =CONCATENATE(P20,Q20,R20,S20,T20,U20,V20,) -> 30 | M20: =CONCATENATE(Z20,AA20,AB20,AC20,AD20,AE20,AF20) -> PAULO HENRIQUE | N20: =J20-K20 -> 1 | P20: =IFERROR(INDEX($A$2:$A$501,MATCH($I20&P$1,$F$2:$F$501,0)),"") -> 30 | Q20: =IFERROR(", "&INDEX($A$2:$A$501,MATCH($I20&Q$1,$F$2:$F$501,0)),"") | R20: =IFERROR(", "&INDEX($A$2:$A$501,MATCH($I20&R$1,$F$2:$F$501,0)),"") | S20: =IFERROR(", "&INDEX($A$2:$A$501,MATCH($I20&S$1,$F$2:$F$501,0)),"") | T20: =IFERROR(", "&INDEX($A$2:$A$501,MATCH($I20&T$1,$F$2:$F$501,0)),"") | U20: =IFERROR(", "&INDEX($A$2:$A$501,MATCH($I20&U$1,$F$2:$F$501,0)),"") | V20: =IFERROR(", "&INDEX($A$2:$A$501,MATCH($I20&V$1,$F$2:$F$501,0)),"") | Z20: =IFERROR(INDEX($B$2:$B$501,MATCH($I20&Z$1,$F$2:$F$501,0)),"") -> PAULO HENRIQUE | AA20: =IFERROR(" ,"&INDEX($B$2:$B$501,MATCH($I20&AA$1,$F$2:$F$501,0)),"") | AB20: =IFERROR(" ,"&INDEX($B$2:$B$501,MATCH($I20&AB$1,$F$2:$F$501,0)),"") | AC20: =IFERROR(" ,"&INDEX($B$2:$B$501,MATCH($I20&AC$1,$F$2:$F$501,0)),"") | AD20: =IFERROR(" ,"&INDEX($B$2:$B$501,MATCH($I20&AD$1,$F$2:$F$501,0)),"") | AE20: =IFERROR(" ,"&INDEX($B$2:$B$501,MATCH($I20&AE$1,$F$2:$F$501,0)),"") | AF20: =IFERROR(" ,"&INDEX($B$2:$B$501,MATCH($I20&AF$1,$F$2:$F$501,0)),"") | AV20: 19 | AW20: GILSON | BM20: 19 | BN20: GILSON pg | BO20: =VLOOKUP(BM20,A:B,2,0) -> GILSON pg | BP20: =BO20=BN20 -> TRUE
A21: 20 | B21: RICARDO SANTOS | C21: 2037150399 | D21: ok | E21: =COUNTIF($C$1:C21,C21) -> 2 | F21: =C21&E21 -> 20371503992 | G21: =IF(IFERROR(FIND("pg",LOWER(B21)),0)=0,0,1) -> 0 | H21: =IF(IFERROR(FIND("(f)",LOWER(B21)),0)=0,0,1) -> 0 | I21: 2038731605 | J21: =COUNTIF(C:C,I21) -> 1 | K21: =COUNTIFS(C:C,I21,G:G,1)+COUNTIFS(C:C,I21,H:H,1) -> 1 | L21: =CONCATENATE(P21,Q21,R21,S21,T21,U21,V21,) -> 31 | M21: =CONCATENATE(Z21,AA21,AB21,AC21,AD21,AE21,AF21) -> OSNI pg | N21: =J21-K21 -> 0 | P21: =IFERROR(INDEX($A$2:$A$501,MATCH($I21&P$1,$F$2:$F$501,0)),"") -> 31 | Q21: =IFERROR(", "&INDEX($A$2:$A$501,MATCH($I21&Q$1,$F$2:$F$501,0)),"") | R21: =IFERROR(", "&INDEX($A$2:$A$501,MATCH($I21&R$1,$F$2:$F$501,0)),"") | S21: =IFERROR(", "&INDEX($A$2:$A$501,MATCH($I21&S$1,$F$2:$F$501,0)),"") | T21: =IFERROR(", "&INDEX($A$2:$A$501,MATCH($I21&T$1,$F$2:$F$501,0)),"") | U21: =IFERROR(", "&INDEX($A$2:$A$501,MATCH($I21&U$1,$F$2:$F$501,0)),"") | V21: =IFERROR(", "&INDEX($A$2:$A$501,MATCH($I21&V$1,$F$2:$F$501,0)),"") | Z21: =IFERROR(INDEX($B$2:$B$501,MATCH($I21&Z$1,$F$2:$F$501,0)),"") -> OSNI pg | AA21: =IFERROR(" ,"&INDEX($B$2:$B$501,MATCH($I21&AA$1,$F$2:$F$501,0)),"") | AB21: =IFERROR(" ,"&INDEX($B$2:$B$501,MATCH($I21&AB$1,$F$2:$F$501,0)),"") | AC21: =IFERROR(" ,"&INDEX($B$2:$B$501,MATCH($I21&AC$1,$F$2:$F$501,0)),"") | AD21: =IFERROR(" ,"&INDEX($B$2:$B$501,MATCH($I21&AD$1,$F$2:$F$501,0)),"") | AE21: =IFERROR(" ,"&INDEX($B$2:$B$501,MATCH($I21&AE$1,$F$2:$F$501,0)),"") | AF21: =IFERROR(" ,"&INDEX($B$2:$B$501,MATCH($I21&AF$1,$F$2:$F$501,0)),"") | AV21: 20 | AW21: RICARDO SANTOS | BM21: 20 | BN21: RICARDO SANTOS | BO21: =VLOOKUP(BM21,A:B,2,0) -> RICARDO SANTOS | BP21: =BO21=BN21 -> TRUE
A22: 21 | B22: SOLON pg | C22: 2033490246 | D22: ok | E22: =COUNTIF($C$1:C22,C22) -> 1 | F22: =C22&E22 -> 20334902461 | G22: =IF(IFERROR(FIND("pg",LOWER(B22)),0)=0,0,1) -> 1 | H22: =IF(IFERROR(FIND("(f)",LOWER(B22)),0)=0,0,1) -> 0 | I22: 2035595696 | J22: =COUNTIF(C:C,I22) -> 1 | K22: =COUNTIFS(C:C,I22,G:G,1)+COUNTIFS(C:C,I22,H:H,1) -> 1 | L22: =CONCATENATE(P22,Q22,R22,S22,T22,U22,V22,) -> 33 | M22: =CONCATENATE(Z22,AA22,AB22,AC22,AD22,AE22,AF22) -> JAIRO pg | N22: =J22-K22 -> 0 | P22: =IFERROR(INDEX($A$2:$A$501,MATCH($I22&P$1,$F$2:$F$501,0)),"") -> 33 | Q22: =IFERROR(", "&INDEX($A$2:$A$501,MATCH($I22&Q$1,$F$2:$F$501,0)),"") | R22: =IFERROR(", "&INDEX($A$2:$A$501,MATCH($I22&R$1,$F$2:$F$501,0)),"") | S22: =IFERROR(", "&INDEX($A$2:$A$501,MATCH($I22&S$1,$F$2:$F$501,0)),"") | T22: =IFERROR(", "&INDEX($A$2:$A$501,MATCH($I22&T$1,$F$2:$F$501,0)),"") | U22: =IFERROR(", "&INDEX($A$2:$A$501,MATCH($I22&U$1,$F$2:$F$501,0)),"") | V22: =IFERROR(", "&INDEX($A$2:$A$501,MATCH($I22&V$1,$F$2:$F$501,0)),"") | Z22: =IFERROR(INDEX($B$2:$B$501,MATCH($I22&Z$1,$F$2:$F$501,0)),"") -> JAIRO pg | AA22: =IFERROR(" ,"&INDEX($B$2:$B$501,MATCH($I22&AA$1,$F$2:$F$501,0)),"") | AB22: =IFERROR(" ,"&INDEX($B$2:$B$501,MATCH($I22&AB$1,$F$2:$F$501,0)),"") | AC22: =IFERROR(" ,"&INDEX($B$2:$B$501,MATCH($I22&AC$1,$F$2:$F$501,0)),"") | AD22: =IFERROR(" ,"&INDEX($B$2:$B$501,MATCH($I22&AD$1,$F$2:$F$501,0)),"") | AE22: =IFERROR(" ,"&INDEX($B$2:$B$501,MATCH($I22&AE$1,$F$2:$F$501,0)),"") | AF22: =IFERROR(" ,"&INDEX($B$2:$B$501,MATCH($I22&AF$1,$F$2:$F$501,0)),"") | AV22: 21 | AW22: SOLON pg | BM22: 21 | BN22: SOLON pg | BO22: =VLOOKUP(BM22,A:B,2,0) -> SOLON pg | BP22: =BO22=BN22 -> TRUE
A23: 22 | B23: BOY pg | C23: 9144975684 | D23: ok | E23: =COUNTIF($C$1:C23,C23) -> 1 | F23: =C23&E23 -> 91449756841 | G23: =IF(IFERROR(FIND("pg",LOWER(B23)),0)=0,0,1) -> 1 | H23: =IF(IFERROR(FIND("(f)",LOWER(B23)),0)=0,0,1) -> 0 | I23: 2039534887 | J23: =COUNTIF(C:C,I23) -> 3 | K23: =COUNTIFS(C:C,I23,G:G,1)+COUNTIFS(C:C,I23,H:H,1) -> 3 | L23: =CONCATENATE(P23,Q23,R23,S23,T23,U23,V23,) -> 34, 167, 423 | M23: =CONCATENATE(Z23,AA23,AB23,AC23,AD23,AE23,AF23) -> Two (Allisson) pg ,Two (Allisson)pg ,Two (Allisson) (f) | N23: =J23-K23 -> 0 | P23: =IFERROR(INDEX($A$2:$A$501,MATCH($I23&P$1,$F$2:$F$501,0)),"") -> 34 | Q23: =IFERROR(", "&INDEX($A$2:$A$501,MATCH($I23&Q$1,$F$2:$F$501,0)),"") -> , 167 | R23: =IFERROR(", "&INDEX($A$2:$A$501,MATCH($I23&R$1,$F$2:$F$501,0)),"") -> , 423 | S23: =IFERROR(", "&INDEX($A$2:$A$501,MATCH($I23&S$1,$F$2:$F$501,0)),"") | T23: =IFERROR(", "&INDEX($A$2:$A$501,MATCH($I23&T$1,$F$2:$F$501,0)),"") | U23: =IFERROR(", "&INDEX($A$2:$A$501,MATCH($I23&U$1,$F$2:$F$501,0)),"") | V23: =IFERROR(", "&INDEX($A$2:$A$501,MATCH($I23&V$1,$F$2:$F$501,0)),"") | Z23: =IFERROR(INDEX($B$2:$B$501,MATCH($I23&Z$1,$F$2:$F$501,0)),"") -> Two (Allisson) pg | AA23: =IFERROR(" ,"&INDEX($B$2:$B$501,MATCH($I23&AA$1,$F$2:$F$501,0)),"") -> ,Two (Allisson)pg | AB23: =IFERROR(" ,"&INDEX($B$2:$B$501,MATCH($I23&AB$1,$F$2:$F$501,0)),"") -> ,Two (Allisson) (f) | AC23: =IFERROR(" ,"&INDEX($B$2:$B$501,MATCH($I23&AC$1,$F$2:$F$501,0)),"") | AD23: =IFERROR(" ,"&INDEX($B$2:$B$501,MATCH($I23&AD$1,$F$2:$F$501,0)),"") | AE23: =IFERROR(" ,"&INDEX($B$2:$B$501,MATCH($I23&AE$1,$F$2:$F$501,0)),"") | AF23: =IFERROR(" ,"&INDEX($B$2:$B$501,MATCH($I23&AF$1,$F$2:$F$501,0)),"") | AV23: 22 | AW23: BOY | BM23: 22 | BN23: BOY | BO23: =VLOOKUP(BM23,A:B,2,0) -> BOY pg | BP23: =BO23=BN23 -> FALSE
A24: 23 | B24: SERGIO | C24: 2038580805 | D24: ok | E24: =COUNTIF($C$1:C24,C24) -> 2 | F24: =C24&E24 -> 20385808052 | G24: =IF(IFERROR(FIND("pg",LOWER(B24)),0)=0,0,1) -> 0 | H24: =IF(IFERROR(FIND("(f)",LOWER(B24)),0)=0,0,1) -> 0 | I24: 2032437348 | J24: =COUNTIF(C:C,I24) -> 1 | K24: =COUNTIFS(C:C,I24,G:G,1)+COUNTIFS(C:C,I24,H:H,1) -> 0 | L24: =CONCATENATE(P24,Q24,R24,S24,T24,U24,V24,) -> 35 | M24: =CONCATENATE(Z24,AA24,AB24,AC24,AD24,AE24,AF24) -> BETO | N24: =J24-K24 -> 1 | P24: =IFERROR(INDEX($A$2:$A$501,MATCH($I24&P$1,$F$2:$F$501,0)),"") -> 35 | Q24: =IFERROR(", "&INDEX($A$2:$A$501,MATCH($I24&Q$1,$F$2:$F$501,0)),"") | R24: =IFERROR(", "&INDEX($A$2:$A$501,MATCH($I24&R$1,$F$2:$F$501,0)),"") | S24: =IFERROR(", "&INDEX($A$2:$A$501,MATCH($I24&S$1,$F$2:$F$501,0)),"") | T24: =IFERROR(", "&INDEX($A$2:$A$501,MATCH($I24&T$1,$F$2:$F$501,0)),"") | U24: =IFERROR(", "&INDEX($A$2:$A$501,MATCH($I24&U$1,$F$2:$F$501,0)),"") | V24: =IFERROR(", "&INDEX($A$2:$A$501,MATCH($I24&V$1,$F$2:$F$501,0)),"") | Z24: =IFERROR(INDEX($B$2:$B$501,MATCH($I24&Z$1,$F$2:$F$501,0)),"") -> BETO | AA24: =IFERROR(" ,"&INDEX($B$2:$B$501,MATCH($I24&AA$1,$F$2:$F$501,0)),"") | AB24: =IFERROR(" ,"&INDEX($B$2:$B$501,MATCH($I24&AB$1,$F$2:$F$501,0)),"") | AC24: =IFERROR(" ,"&INDEX($B$2:$B$501,MATCH($I24&AC$1,$F$2:$F$501,0)),"") | AD24: =IFERROR(" ,"&INDEX($B$2:$B$501,MATCH($I24&AD$1,$F$2:$F$501,0)),"") | AE24: =IFERROR(" ,"&INDEX($B$2:$B$501,MATCH($I24&AE$1,$F$2:$F$501,0)),"") | AF24: =IFERROR(" ,"&INDEX($B$2:$B$501,MATCH($I24&AF$1,$F$2:$F$501,0)),"") | AV24: 23 | AW24: SERGIO | BM24: 23 | BN24: SERGIO | BO24: =VLOOKUP(BM24,A:B,2,0) -> SERGIO | BP24: =BO24=BN24 -> TRUE
A25: 24 | E25: =COUNTIF($C$1:C25,C25) -> 0 | F25: =C25&E25 -> 0 | G25: =IF(IFERROR(FIND("pg",LOWER(B25)),0)=0,0,1) -> 0 | H25: =IF(IFERROR(FIND("(f)",LOWER(B25)),0)=0,0,1) -> 0 | I25: 2035158719 | J25: =COUNTIF(C:C,I25) -> 4 | K25: =COUNTIFS(C:C,I25,G:G,1)+COUNTIFS(C:C,I25,H:H,1) -> 4 | L25: =CONCATENATE(P25,Q25,R25,S25,T25,U25,V25,) -> 36, 54, 55, 88 | M25: =CONCATENATE(Z25,AA25,AB25,AC25,AD25,AE25,AF25) -> ROGERINHO pg ,ROGERINHO pg ,ARLON pg ,CESAR pg | N25: =J25-K25 -> 0 | P25: =IFERROR(INDEX($A$2:$A$501,MATCH($I25&P$1,$F$2:$F$501,0)),"") -> 36 | Q25: =IFERROR(", "&INDEX($A$2:$A$501,MATCH($I25&Q$1,$F$2:$F$501,0)),"") -> , 54 | R25: =IFERROR(", "&INDEX($A$2:$A$501,MATCH($I25&R$1,$F$2:$F$501,0)),"") -> , 55 | S25: =IFERROR(", "&INDEX($A$2:$A$501,MATCH($I25&S$1,$F$2:$F$501,0)),"") -> , 88 | T25: =IFERROR(", "&INDEX($A$2:$A$501,MATCH($I25&T$1,$F$2:$F$501,0)),"") | U25: =IFERROR(", "&INDEX($A$2:$A$501,MATCH($I25&U$1,$F$2:$F$501,0)),"") | V25: =IFERROR(", "&INDEX($A$2:$A$501,MATCH($I25&V$1,$F$2:$F$501,0)),"") | Z25: =IFERROR(INDEX($B$2:$B$501,MATCH($I25&Z$1,$F$2:$F$501,0)),"") -> ROGERINHO pg | AA25: =IFERROR(" ,"&INDEX($B$2:$B$501,MATCH($I25&AA$1,$F$2:$F$501,0)),"") -> ,ROGERINHO pg | AB25: =IFERROR(" ,"&INDEX($B$2:$B$501,MATCH($I25&AB$1,$F$2:$F$501,0)),"") -> ,ARLON pg | AC25: =IFERROR(" ,"&INDEX($B$2:$B$501,MATCH($I25&AC$1,$F$2:$F$501,0)),"") -> ,CESAR pg | AD25: =IFERROR(" ,"&INDEX($B$2:$B$501,MATCH($I25&AD$1,$F$2:$F$501,0)),"") | AE25: =IFERROR(" ,"&INDEX($B$2:$B$501,MATCH($I25&AE$1,$F$2:$F$501,0)),"") | AF25: =IFERROR(" ,"&INDEX($B$2:$B$501,MATCH($I25&AF$1,$F$2:$F$501,0)),"") | AV25: 24 | AW25: ALEXANDRE DA SILVA | BM25: 24 | BN25: ALEXANDRE DA SILVA | BO25: =VLOOKUP(BM25,A:B,2,0) -> 0 | BP25: =BO25=BN25 -> FALSE
A26: 25 | B26: TULIO pg | C26: 9144337335 | D26: ok | E26: =COUNTIF($C$1:C26,C26) -> 2 | F26: =C26&E26 -> 91443373352 | G26: =IF(IFERROR(FIND("pg",LOWER(B26)),0)=0,0,1) -> 1 | H26: =IF(IFERROR(FIND("(f)",LOWER(B26)),0)=0,0,1) -> 0 | I26: 2039483635 | J26: =COUNTIF(C:C,I26) -> 2 | K26: =COUNTIFS(C:C,I26,G:G,1)+COUNTIFS(C:C,I26,H:H,1) -> 0 | L26: =CONCATENATE(P26,Q26,R26,S26,T26,U26,V26,) -> 37, 52 | M26: =CONCATENATE(Z26,AA26,AB26,AC26,AD26,AE26,AF26) -> MARTINS ,MARTINS | N26: =J26-K26 -> 2 | P26: =IFERROR(INDEX($A$2:$A$501,MATCH($I26&P$1,$F$2:$F$501,0)),"") -> 37 | Q26: =IFERROR(", "&INDEX($A$2:$A$501,MATCH($I26&Q$1,$F$2:$F$501,0)),"") -> , 52 | R26: =IFERROR(", "&INDEX($A$2:$A$501,MATCH($I26&R$1,$F$2:$F$501,0)),"") | S26: =IFERROR(", "&INDEX($A$2:$A$501,MATCH($I26&S$1,$F$2:$F$501,0)),"") | T26: =IFERROR(", "&INDEX($A$2:$A$501,MATCH($I26&T$1,$F$2:$F$501,0)),"") | U26: =IFERROR(", "&INDEX($A$2:$A$501,MATCH($I26&U$1,$F$2:$F$501,0)),"") | V26: =IFERROR(", "&INDEX($A$2:$A$501,MATCH($I26&V$1,$F$2:$F$501,0)),"") | Z26: =IFERROR(INDEX($B$2:$B$501,MATCH($I26&Z$1,$F$2:$F$501,0)),"") -> MARTINS | AA26: =IFERROR(" ,"&INDEX($B$2:$B$501,MATCH($I26&AA$1,$F$2:$F$501,0)),"") -> ,MARTINS | AB26: =IFERROR(" ,"&INDEX($B$2:$B$501,MATCH($I26&AB$1,$F$2:$F$501,0)),"") | AC26: =IFERROR(" ,"&INDEX($B$2:$B$501,MATCH($I26&AC$1,$F$2:$F$501,0)),"") | AD26: =IFERROR(" ,"&INDEX($B$2:$B$501,MATCH($I26&AD$1,$F$2:$F$501,0)),"") | AE26: =IFERROR(" ,"&INDEX($B$2:$B$501,MATCH($I26&AE$1,$F$2:$F$501,0)),"") | AF26: =IFERROR(" ,"&INDEX($B$2:$B$501,MATCH($I26&AF$1,$F$2:$F$501,0)),"") | AV26: 25 | AW26: TULIO | BM26: 25 | BN26: TULIO pg | BO26: =VLOOKUP(BM26,A:B,2,0) -> TULIO pg | BP26: =BO26=BN26 -> TRUE
A27: 26 | B27: FERNANDO XARA | C27: 2039943998 | D27: ok | E27: =COUNTIF($C$1:C27,C27) -> 1 | F27: =C27&E27 -> 20399439981 | G27: =IF(IFERROR(FIND("pg",LOWER(B27)),0)=0,0,1) -> 0 | H27: =IF(IFERROR(FIND("(f)",LOWER(B27)),0)=0,0,1) -> 0 | I27: 2038566452 | J27: =COUNTIF(C:C,I27) -> 2 | K27: =COUNTIFS(C:C,I27,G:G,1)+COUNTIFS(C:C,I27,H:H,1) -> 0 | L27: =CONCATENATE(P27,Q27,R27,S27,T27,U27,V27,) -> 39, 150 | M27: =CONCATENATE(Z27,AA27,AB27,AC27,AD27,AE27,AF27) -> SANZIO ,SANZIO | N27: =J27-K27 -> 2 | P27: =IFERROR(INDEX($A$2:$A$501,MATCH($I27&P$1,$F$2:$F$501,0)),"") -> 39 | Q27: =IFERROR(", "&INDEX($A$2:$A$501,MATCH($I27&Q$1,$F$2:$F$501,0)),"") -> , 150 | R27: =IFERROR(", "&INDEX($A$2:$A$501,MATCH($I27&R$1,$F$2:$F$501,0)),"") | S27: =IFERROR(", "&INDEX($A$2:$A$501,MATCH($I27&S$1,$F$2:$F$501,0)),"") | T27: =IFERROR(", "&INDEX($A$2:$A$501,MATCH($I27&T$1,$F$2:$F$501,0)),"") | U27: =IFERROR(", "&INDEX($A$2:$A$501,MATCH($I27&U$1,$F$2:$F$501,0)),"") | V27: =IFERROR(", "&INDEX($A$2:$A$501,MATCH($I27&V$1,$F$2:$F$501,0)),"") | Z27: =IFERROR(INDEX($B$2:$B$501,MATCH($I27&Z$1,$F$2:$F$501,0)),"") -> SANZIO | AA27: =IFERROR(" ,"&INDEX($B$2:$B$501,MATCH($I27&AA$1,$F$2:$F$501,0)),"") -> ,SANZIO | AB27: =IFERROR(" ,"&INDEX($B$2:$B$501,MATCH($I27&AB$1,$F$2:$F$501,0)),"") | AC27: =IFERROR(" ,"&INDEX($B$2:$B$501,MATCH($I27&AC$1,$F$2:$F$501,0)),"") | AD27: =IFERROR(" ,"&INDEX($B$2:$B$501,MATCH($I27&AD$1,$F$2:$F$501,0)),"") | AE27: =IFERROR(" ,"&INDEX($B$2:$B$501,MATCH($I27&AE$1,$F$2:$F$501,0)),"") | AF27: =IFERROR(" ,"&INDEX($B$2:$B$501,MATCH($I27&AF$1,$F$2:$F$501,0)),"") | AV27: 26 | AW27: FERNANDO XARA | BM27: 26 | BN27: FERNANDO XARA | BO27: =VLOOKUP(BM27,A:B,2,0) -> FERNANDO XARA | BP27: =BO27=BN27 -> TRUE
A28: 27 | B28: GILSON pg | C28: 2032803585 | D28: ok | E28: =COUNTIF($C$1:C28,C28) -> 2 | F28: =C28&E28 -> 20328035852 | G28: =IF(IFERROR(FIND("pg",LOWER(B28)),0)=0,0,1) -> 1 | H28: =IF(IFERROR(FIND("(f)",LOWER(B28)),0)=0,0,1) -> 0 | I28: 2033606365 | J28: =COUNTIF(C:C,I28) -> 1 | K28: =COUNTIFS(C:C,I28,G:G,1)+COUNTIFS(C:C,I28,H:H,1) -> 0 | L28: =CONCATENATE(P28,Q28,R28,S28,T28,U28,V28,) -> 40 | M28: =CONCATENATE(Z28,AA28,AB28,AC28,AD28,AE28,AF28) -> MARCELAO | N28: =J28-K28 -> 1 | P28: =IFERROR(INDEX($A$2:$A$501,MATCH($I28&P$1,$F$2:$F$501,0)),"") -> 40 | Q28: =IFERROR(", "&INDEX($A$2:$A$501,MATCH($I28&Q$1,$F$2:$F$501,0)),"") | R28: =IFERROR(", "&INDEX($A$2:$A$501,MATCH($I28&R$1,$F$2:$F$501,0)),"") | S28: =IFERROR(", "&INDEX($A$2:$A$501,MATCH($I28&S$1,$F$2:$F$501,0)),"") | T28: =IFERROR(", "&INDEX($A$2:$A$501,MATCH($I28&T$1,$F$2:$F$501,0)),"") | U28: =IFERROR(", "&INDEX($A$2:$A$501,MATCH($I28&U$1,$F$2:$F$501,0)),"") | V28: =IFERROR(", "&INDEX($A$2:$A$501,MATCH($I28&V$1,$F$2:$F$501,0)),"") | Z28: =IFERROR(INDEX($B$2:$B$501,MATCH($I28&Z$1,$F$2:$F$501,0)),"") -> MARCELAO | AA28: =IFERROR(" ,"&INDEX($B$2:$B$501,MATCH($I28&AA$1,$F$2:$F$501,0)),"") | AB28: =IFERROR(" ,"&INDEX($B$2:$B$501,MATCH($I28&AB$1,$F$2:$F$501,0)),"") | AC28: =IFERROR(" ,"&INDEX($B$2:$B$501,MATCH($I28&AC$1,$F$2:$F$501,0)),"") | AD28: =IFERROR(" ,"&INDEX($B$2:$B$501,MATCH($I28&AD$1,$F$2:$F$501,0)),"") | AE28: =IFERROR(" ,"&INDEX($B$2:$B$501,MATCH($I28&AE$1,$F$2:$F$501,0)),"") | AF28: =IFERROR(" ,"&INDEX($B$2:$B$501,MATCH($I28&AF$1,$F$2:$F$501,0)),"") | AV28: 27 | AW28: GILSON | BM28: 27 | BN28: GILSON pg | BO28: =VLOOKUP(BM28,A:B,2,0) -> GILSON pg | BP28: =BO28=BN28 -> TRUE
A29: 28 | B29: WELVERTON | C29: 2033607352 | D29: em nome deCristiano | E29: =COUNTIF($C$1:C29,C29) -> 1 | F29: =C29&E29 -> 20336073521 | G29: =IF(IFERROR(FIND("pg",LOWER(B29)),0)=0,0,1) -> 0 | H29: =IF(IFERROR(FIND("(f)",LOWER(B29)),0)=0,0,1) -> 0 | I29: 4753621811 | J29: =COUNTIF(C:C,I29) -> 2 | K29: =COUNTIFS(C:C,I29,G:G,1)+COUNTIFS(C:C,I29,H:H,1) -> 0 | L29: =CONCATENATE(P29,Q29,R29,S29,T29,U29,V29,) -> 41, 50 | M29: =CONCATENATE(Z29,AA29,AB29,AC29,AD29,AE29,AF29) -> SIMONE ,SIMONE | N29: =J29-K29 -> 2 | P29: =IFERROR(INDEX($A$2:$A$501,MATCH($I29&P$1,$F$2:$F$501,0)),"") -> 41 | Q29: =IFERROR(", "&INDEX($A$2:$A$501,MATCH($I29&Q$1,$F$2:$F$501,0)),"") -> , 50 | R29: =IFERROR(", "&INDEX($A$2:$A$501,MATCH($I29&R$1,$F$2:$F$501,0)),"") | S29: =IFERROR(", "&INDEX($A$2:$A$501,MATCH($I29&S$1,$F$2:$F$501,0)),"") | T29: =IFERROR(", "&INDEX($A$2:$A$501,MATCH($I29&T$1,$F$2:$F$501,0)),"") | U29: =IFERROR(", "&INDEX($A$2:$A$501,MATCH($I29&U$1,$F$2:$F$501,0)),"") | V29: =IFERROR(", "&INDEX($A$2:$A$501,MATCH($I29&V$1,$F$2:$F$501,0)),"") | Z29: =IFERROR(INDEX($B$2:$B$501,MATCH($I29&Z$1,$F$2:$F$501,0)),"") -> SIMONE | AA29: =IFERROR(" ,"&INDEX($B$2:$B$501,MATCH($I29&AA$1,$F$2:$F$501,0)),"") -> ,SIMONE | AB29: =IFERROR(" ,"&INDEX($B$2:$B$501,MATCH($I29&AB$1,$F$2:$F$501,0)),"") | AC29: =IFERROR(" ,"&INDEX($B$2:$B$501,MATCH($I29&AC$1,$F$2:$F$501,0)),"") | AD29: =IFERROR(" ,"&INDEX($B$2:$B$501,MATCH($I29&AD$1,$F$2:$F$501,0)),"") | AE29: =IFERROR(" ,"&INDEX($B$2:$B$501,MATCH($I29&AE$1,$F$2:$F$501,0)),"") | AF29: =IFERROR(" ,"&INDEX($B$2:$B$501,MATCH($I29&AF$1,$F$2:$F$501,0)),"") | AV29: 28 | AW29: WELVERTON | BM29: 28 | BN29: WELVERTON | BO29: =VLOOKUP(BM29,A:B,2,0) -> WELVERTON | BP29: =BO29=BN29 -> TRUE
A30: 29 | B30: SOLON pg | C30: 2033490246 | D30: ok | E30: =COUNTIF($C$1:C30,C30) -> 2 | F30: =C30&E30 -> 20334902462 | G30: =IF(IFERROR(FIND("pg",LOWER(B30)),0)=0,0,1) -> 1 | H30: =IF(IFERROR(FIND("(f)",LOWER(B30)),0)=0,0,1) -> 0 | I30: 4759884337 | J30: =COUNTIF(C:C,I30) -> 1 | K30: =COUNTIFS(C:C,I30,G:G,1)+COUNTIFS(C:C,I30,H:H,1) -> 0 | L30: =CONCATENATE(P30,Q30,R30,S30,T30,U30,V30,) -> 42 | M30: =CONCATENATE(Z30,AA30,AB30,AC30,AD30,AE30,AF30) -> ALESSANDRO BARBOSA (LEO BAIA) | N30: =J30-K30 -> 1 | P30: =IFERROR(INDEX($A$2:$A$501,MATCH($I30&P$1,$F$2:$F$501,0)),"") -> 42 | Q30: =IFERROR(", "&INDEX($A$2:$A$501,MATCH($I30&Q$1,$F$2:$F$501,0)),"") | R30: =IFERROR(", "&INDEX($A$2:$A$501,MATCH($I30&R$1,$F$2:$F$501,0)),"") | S30: =IFERROR(", "&INDEX($A$2:$A$501,MATCH($I30&S$1,$F$2:$F$501,0)),"") | T30: =IFERROR(", "&INDEX($A$2:$A$501,MATCH($I30&T$1,$F$2:$F$501,0)),"") | U30: =IFERROR(", "&INDEX($A$2:$A$501,MATCH($I30&U$1,$F$2:$F$501,0)),"") | V30: =IFERROR(", "&INDEX($A$2:$A$501,MATCH($I30&V$1,$F$2:$F$501,0)),"") | Z30: =IFERROR(INDEX($B$2:$B$501,MATCH($I30&Z$1,$F$2:$F$501,0)),"") -> ALESSANDRO BARBOSA (LEO BAIA) | AA30: =IFERROR(" ,"&INDEX($B$2:$B$501,MATCH($I30&AA$1,$F$2:$F$501,0)),"") | AB30: =IFERROR(" ,"&INDEX($B$2:$B$501,MATCH($I30&AB$1,$F$2:$F$501,0)),"") | AC30: =IFERROR(" ,"&INDEX($B$2:$B$501,MATCH($I30&AC$1,$F$2:$F$501,0)),"") | AD30: =IFERROR(" ,"&INDEX($B$2:$B$501,MATCH($I30&AD$1,$F$2:$F$501,0)),"") | AE30: =IFERROR(" ,"&INDEX($B$2:$B$501,MATCH($I30&AE$1,$F$2:$F$501,0)),"") | AF30: =IFERROR(" ,"&INDEX($B$2:$B$501,MATCH($I30&AF$1,$F$2:$F$501,0)),"") | AV30: 29 | AW30: SOLON pg | BM30: 29 | BN30: SOLON pg | BO30: =VLOOKUP(BM30,A:B,2,0) -> SOLON pg | BP30: =BO30=BN30 -> TRUE
A31: 30 | B31: PAULO HENRIQUE | C31: 5511997219288 | D31: ok | E31: =COUNTIF($C$1:C31,C31) -> 1 | F31: =C31&E31 -> 55119972192881 | G31: =IF(IFERROR(FIND("pg",LOWER(B31)),0)=0,0,1) -> 0 | H31: =IF(IFERROR(FIND("(f)",LOWER(B31)),0)=0,0,1) -> 0 | I31: 5511992712403 | J31: =COUNTIF(C:C,I31) -> 1 | K31: =COUNTIFS(C:C,I31,G:G,1)+COUNTIFS(C:C,I31,H:H,1) -> 0 | L31: =CONCATENATE(P31,Q31,R31,S31,T31,U31,V31,) -> 43 | M31: =CONCATENATE(Z31,AA31,AB31,AC31,AD31,AE31,AF31) -> IGOR | N31: =J31-K31 -> 1 | P31: =IFERROR(INDEX($A$2:$A$501,MATCH($I31&P$1,$F$2:$F$501,0)),"") -> 43 | Q31: =IFERROR(", "&INDEX($A$2:$A$501,MATCH($I31&Q$1,$F$2:$F$501,0)),"") | R31: =IFERROR(", "&INDEX($A$2:$A$501,MATCH($I31&R$1,$F$2:$F$501,0)),"") | S31: =IFERROR(", "&INDEX($A$2:$A$501,MATCH($I31&S$1,$F$2:$F$501,0)),"") | T31: =IFERROR(", "&INDEX($A$2:$A$501,MATCH($I31&T$1,$F$2:$F$501,0)),"") | U31: =IFERROR(", "&INDEX($A$2:$A$501,MATCH($I31&U$1,$F$2:$F$501,0)),"") | V31: =IFERROR(", "&INDEX($A$2:$A$501,MATCH($I31&V$1,$F$2:$F$501,0)),"") | Z31: =IFERROR(INDEX($B$2:$B$501,MATCH($I31&Z$1,$F$2:$F$501,0)),"") -> IGOR | AA31: =IFERROR(" ,"&INDEX($B$2:$B$501,MATCH($I31&AA$1,$F$2:$F$501,0)),"") | AB31: =IFERROR(" ,"&INDEX($B$2:$B$501,MATCH($I31&AB$1,$F$2:$F$501,0)),"") | AC31: =IFERROR(" ,"&INDEX($B$2:$B$501,MATCH($I31&AC$1,$F$2:$F$501,0)),"") | AD31: =IFERROR(" ,"&INDEX($B$2:$B$501,MATCH($I31&AD$1,$F$2:$F$501,0)),"") | AE31: =IFERROR(" ,"&INDEX($B$2:$B$501,MATCH($I31&AE$1,$F$2:$F$501,0)),"") | AF31: =IFERROR(" ,"&INDEX($B$2:$B$501,MATCH($I31&AF$1,$F$2:$F$501,0)),"") | AV31: 30 | AW31: PAULO HENRIQUE | BM31: 30 | BN31: PAULO HENRIQUE | BO31: =VLOOKUP(BM31,A:B,2,0) -> PAULO HENRIQUE | BP31: =BO31=BN31 -> TRUE
A32: 31 | B32: OSNI pg | C32: 2038731605 | D32: ok | E32: =COUNTIF($C$1:C32,C32) -> 1 | F32: =C32&E32 -> 20387316051 | G32: =IF(IFERROR(FIND("pg",LOWER(B32)),0)=0,0,1) -> 1 | H32: =IF(IFERROR(FIND("(f)",LOWER(B32)),0)=0,0,1) -> 0 | I32: 2033607352 | J32: =COUNTIF(C:C,I32) -> 3 | K32: =COUNTIFS(C:C,I32,G:G,1)+COUNTIFS(C:C,I32,H:H,1) -> 0 | L32: =CONCATENATE(P32,Q32,R32,S32,T32,U32,V32,) -> 28, 44, 137 | M32: =CONCATENATE(Z32,AA32,AB32,AC32,AD32,AE32,AF32) -> WELVERTON ,CRISTIANO ,CRISTIANO | N32: =J32-K32 -> 3 | P32: =IFERROR(INDEX($A$2:$A$501,MATCH($I32&P$1,$F$2:$F$501,0)),"") -> 28 | Q32: =IFERROR(", "&INDEX($A$2:$A$501,MATCH($I32&Q$1,$F$2:$F$501,0)),"") -> , 44 | R32: =IFERROR(", "&INDEX($A$2:$A$501,MATCH($I32&R$1,$F$2:$F$501,0)),"") -> , 137 | S32: =IFERROR(", "&INDEX($A$2:$A$501,MATCH($I32&S$1,$F$2:$F$501,0)),"") | T32: =IFERROR(", "&INDEX($A$2:$A$501,MATCH($I32&T$1,$F$2:$F$501,0)),"") | U32: =IFERROR(", "&INDEX($A$2:$A$501,MATCH($I32&U$1,$F$2:$F$501,0)),"") | V32: =IFERROR(", "&INDEX($A$2:$A$501,MATCH($I32&V$1,$F$2:$F$501,0)),"") | Z32: =IFERROR(INDEX($B$2:$B$501,MATCH($I32&Z$1,$F$2:$F$501,0)),"") -> WELVERTON | AA32: =IFERROR(" ,"&INDEX($B$2:$B$501,MATCH($I32&AA$1,$F$2:$F$501,0)),"") -> ,CRISTIANO | AB32: =IFERROR(" ,"&INDEX($B$2:$B$501,MATCH($I32&AB$1,$F$2:$F$501,0)),"") -> ,CRISTIANO | AC32: =IFERROR(" ,"&INDEX($B$2:$B$501,MATCH($I32&AC$1,$F$2:$F$501,0)),"") | AD32: =IFERROR(" ,"&INDEX($B$2:$B$501,MATCH($I32&AD$1,$F$2:$F$501,0)),"") | AE32: =IFERROR(" ,"&INDEX($B$2:$B$501,MATCH($I32&AE$1,$F$2:$F$501,0)),"") | AF32: =IFERROR(" ,"&INDEX($B$2:$B$501,MATCH($I32&AF$1,$F$2:$F$501,0)),"") | AV32: 31 | AW32: OSNI | BM32: 31 | BN32: OSNI | BO32: =VLOOKUP(BM32,A:B,2,0) -> OSNI pg | BP32: =BO32=BN32 -> FALSE
A33: 32 | B33: HENRY QUINTANA | D33: não loc | E33: =COUNTIF($C$1:C33,C33) -> 0 | F33: =C33&E33 -> 0 | G33: =IF(IFERROR(FIND("pg",LOWER(B33)),0)=0,0,1) -> 0 | H33: =IF(IFERROR(FIND("(f)",LOWER(B33)),0)=0,0,1) -> 0 | I33: 2038185657 | J33: =COUNTIF(C:C,I33) -> 2 | K33: =COUNTIFS(C:C,I33,G:G,1)+COUNTIFS(C:C,I33,H:H,1) -> 2 | L33: =CONCATENATE(P33,Q33,R33,S33,T33,U33,V33,) -> 46, 110 | M33: =CONCATENATE(Z33,AA33,AB33,AC33,AD33,AE33,AF33) -> JESSICA pg ,JESSICA pg | N33: =J33-K33 -> 0 | P33: =IFERROR(INDEX($A$2:$A$501,MATCH($I33&P$1,$F$2:$F$501,0)),"") -> 46 | Q33: =IFERROR(", "&INDEX($A$2:$A$501,MATCH($I33&Q$1,$F$2:$F$501,0)),"") -> , 110 | R33: =IFERROR(", "&INDEX($A$2:$A$501,MATCH($I33&R$1,$F$2:$F$501,0)),"") | S33: =IFERROR(", "&INDEX($A$2:$A$501,MATCH($I33&S$1,$F$2:$F$501,0)),"") | T33: =IFERROR(", "&INDEX($A$2:$A$501,MATCH($I33&T$1,$F$2:$F$501,0)),"") | U33: =IFERROR(", "&INDEX($A$2:$A$501,MATCH($I33&U$1,$F$2:$F$501,0)),"") | V33: =IFERROR(", "&INDEX($A$2:$A$501,MATCH($I33&V$1,$F$2:$F$501,0)),"") | Z33: =IFERROR(INDEX($B$2:$B$501,MATCH($I33&Z$1,$F$2:$F$501,0)),"") -> JESSICA pg | AA33: =IFERROR(" ,"&INDEX($B$2:$B$501,MATCH($I33&AA$1,$F$2:$F$501,0)),"") -> ,JESSICA pg | AB33: =IFERROR(" ,"&INDEX($B$2:$B$501,MATCH($I33&AB$1,$F$2:$F$501,0)),"") | AC33: =IFERROR(" ,"&INDEX($B$2:$B$501,MATCH($I33&AC$1,$F$2:$F$501,0)),"") | AD33: =IFERROR(" ,"&INDEX($B$2:$B$501,MATCH($I33&AD$1,$F$2:$F$501,0)),"") | AE33: =IFERROR(" ,"&INDEX($B$2:$B$501,MATCH($I33&AE$1,$F$2:$F$501,0)),"") | AF33: =IFERROR(" ,"&INDEX($B$2:$B$501,MATCH($I33&AF$1,$F$2:$F$501,0)),"") | AV33: 32 | AW33: HENRY QUINTANA | BM33: 32 | BN33: HENRY QUINTANA | BO33: =VLOOKUP(BM33,A:B,2,0) -> HENRY QUINTANA | BP33: =BO33=BN33 -> TRUE
A34: 33 | B34: JAIRO pg | C34: 2035595696 | D34: ok | E34: =COUNTIF($C$1:C34,C34) -> 1 | F34: =C34&E34 -> 20355956961 | G34: =IF(IFERROR(FIND("pg",LOWER(B34)),0)=0,0,1) -> 1 | H34: =IF(IFERROR(FIND("(f)",LOWER(B34)),0)=0,0,1) -> 0 | I34: 2032122279 | J34: =COUNTIF(C:C,I34) -> 3 | K34: =COUNTIFS(C:C,I34,G:G,1)+COUNTIFS(C:C,I34,H:H,1) -> 0 | L34: =CONCATENATE(P34,Q34,R34,S34,T34,U34,V34,) -> 47, 470, 478 | M34: =CONCATENATE(Z34,AA34,AB34,AC34,AD34,AE34,AF34) -> JEREMIAS COSTA ,JEREMIAS COSTA ,JEREMIAS COSTA | N34: =J34-K34 -> 3 | P34: =IFERROR(INDEX($A$2:$A$501,MATCH($I34&P$1,$F$2:$F$501,0)),"") -> 47 | Q34: =IFERROR(", "&INDEX($A$2:$A$501,MATCH($I34&Q$1,$F$2:$F$501,0)),"") -> , 470 | R34: =IFERROR(", "&INDEX($A$2:$A$501,MATCH($I34&R$1,$F$2:$F$501,0)),"") -> , 478 | S34: =IFERROR(", "&INDEX($A$2:$A$501,MATCH($I34&S$1,$F$2:$F$501,0)),"") | T34: =IFERROR(", "&INDEX($A$2:$A$501,MATCH($I34&T$1,$F$2:$F$501,0)),"") | U34: =IFERROR(", "&INDEX($A$2:$A$501,MATCH($I34&U$1,$F$2:$F$501,0)),"") | V34: =IFERROR(", "&INDEX($A$2:$A$501,MATCH($I34&V$1,$F$2:$F$501,0)),"") | Z34: =IFERROR(INDEX($B$2:$B$501,MATCH($I34&Z$1,$F$2:$F$501,0)),"") -> JEREMIAS COSTA | AA34: =IFERROR(" ,"&INDEX($B$2:$B$501,MATCH($I34&AA$1,$F$2:$F$501,0)),"") -> ,JEREMIAS COSTA | AB34: =IFERROR(" ,"&INDEX($B$2:$B$501,MATCH($I34&AB$1,$F$2:$F$501,0)),"") -> ,JEREMIAS COSTA | AC34: =IFERROR(" ,"&INDEX($B$2:$B$501,MATCH($I34&AC$1,$F$2:$F$501,0)),"") | AD34: =IFERROR(" ,"&INDEX($B$2:$B$501,MATCH($I34&AD$1,$F$2:$F$501,0)),"") | AE34: =IFERROR(" ,"&INDEX($B$2:$B$501,MATCH($I34&AE$1,$F$2:$F$501,0)),"") | AF34: =IFERROR(" ,"&INDEX($B$2:$B$501,MATCH($I34&AF$1,$F$2:$F$501,0)),"") | AV34: 33 | AW34: JAIRO | BM34: 33 | BN34: JAIRO pg | BO34: =VLOOKUP(BM34,A:B,2,0) -> JAIRO pg | BP34: =BO34=BN34 -> TRUE
A35: 34 | B35: Two (Allisson) pg | C35: 2039534887 | D35: ok | E35: =COUNTIF($C$1:C35,C35) -> 1 | F35: =C35&E35 -> 20395348871 | G35: =IF(IFERROR(FIND("pg",LOWER(B35)),0)=0,0,1) -> 1 | H35: =IF(IFERROR(FIND("(f)",LOWER(B35)),0)=0,0,1) -> 0 | I35: 2038148765 | J35: =COUNTIF(C:C,I35) -> 1 | K35: =COUNTIFS(C:C,I35,G:G,1)+COUNTIFS(C:C,I35,H:H,1) -> 0 | L35: =CONCATENATE(P35,Q35,R35,S35,T35,U35,V35,) -> 48 | M35: =CONCATENATE(Z35,AA35,AB35,AC35,AD35,AE35,AF35) -> MARCIO CARVALHO | N35: =J35-K35 -> 1 | P35: =IFERROR(INDEX($A$2:$A$501,MATCH($I35&P$1,$F$2:$F$501,0)),"") -> 48 | Q35: =IFERROR(", "&INDEX($A$2:$A$501,MATCH($I35&Q$1,$F$2:$F$501,0)),"") | R35: =IFERROR(", "&INDEX($A$2:$A$501,MATCH($I35&R$1,$F$2:$F$501,0)),"") | S35: =IFERROR(", "&INDEX($A$2:$A$501,MATCH($I35&S$1,$F$2:$F$501,0)),"") | T35: =IFERROR(", "&INDEX($A$2:$A$501,MATCH($I35&T$1,$F$2:$F$501,0)),"") | U35: =IFERROR(", "&INDEX($A$2:$A$501,MATCH($I35&U$1,$F$2:$F$501,0)),"") | V35: =IFERROR(", "&INDEX($A$2:$A$501,MATCH($I35&V$1,$F$2:$F$501,0)),"") | Z35: =IFERROR(INDEX($B$2:$B$501,MATCH($I35&Z$1,$F$2:$F$501,0)),"") -> MARCIO CARVALHO | AA35: =IFERROR(" ,"&INDEX($B$2:$B$501,MATCH($I35&AA$1,$F$2:$F$501,0)),"") | AB35: =IFERROR(" ,"&INDEX($B$2:$B$501,MATCH($I35&AB$1,$F$2:$F$501,0)),"") | AC35: =IFERROR(" ,"&INDEX($B$2:$B$501,MATCH($I35&AC$1,$F$2:$F$501,0)),"") | AD35: =IFERROR(" ,"&INDEX($B$2:$B$501,MATCH($I35&AD$1,$F$2:$F$501,0)),"") | AE35: =IFERROR(" ,"&INDEX($B$2:$B$501,MATCH($I35&AE$1,$F$2:$F$501,0)),"") | AF35: =IFERROR(" ,"&INDEX($B$2:$B$501,MATCH($I35&AF$1,$F$2:$F$501,0)),"") | AV35: 34 | AW35: Two (Allisson) pg | BM35: 34 | BN35: Two (Allisson) pg | BO35: =VLOOKUP(BM35,A:B,2,0) -> Two (Allisson) pg | BP35: =BO35=BN35 -> TRUE
A36: 35 | B36: BETO | C36: 2032437348 | D36: ok | E36: =COUNTIF($C$1:C36,C36) -> 1 | F36: =C36&E36 -> 20324373481 | G36: =IF(IFERROR(FIND("pg",LOWER(B36)),0)=0,0,1) -> 0 | H36: =IF(IFERROR(FIND("(f)",LOWER(B36)),0)=0,0,1) -> 0 | I36: 2036679981 | J36: =COUNTIF(C:C,I36) -> 1 | K36: =COUNTIFS(C:C,I36,G:G,1)+COUNTIFS(C:C,I36,H:H,1) -> 1 | L36: =CONCATENATE(P36,Q36,R36,S36,T36,U36,V36,) -> 49 | M36: =CONCATENATE(Z36,AA36,AB36,AC36,AD36,AE36,AF36) -> RENE pg | N36: =J36-K36 -> 0 | P36: =IFERROR(INDEX($A$2:$A$501,MATCH($I36&P$1,$F$2:$F$501,0)),"") -> 49 | Q36: =IFERROR(", "&INDEX($A$2:$A$501,MATCH($I36&Q$1,$F$2:$F$501,0)),"") | R36: =IFERROR(", "&INDEX($A$2:$A$501,MATCH($I36&R$1,$F$2:$F$501,0)),"") | S36: =IFERROR(", "&INDEX($A$2:$A$501,MATCH($I36&S$1,$F$2:$F$501,0)),"") | T36: =IFERROR(", "&INDEX($A$2:$A$501,MATCH($I36&T$1,$F$2:$F$501,0)),"") | U36: =IFERROR(", "&INDEX($A$2:$A$501,MATCH($I36&U$1,$F$2:$F$501,0)),"") | V36: =IFERROR(", "&INDEX($A$2:$A$501,MATCH($I36&V$1,$F$2:$F$501,0)),"") | Z36: =IFERROR(INDEX($B$2:$B$501,MATCH($I36&Z$1,$F$2:$F$501,0)),"") -> RENE pg | AA36: =IFERROR(" ,"&INDEX($B$2:$B$501,MATCH($I36&AA$1,$F$2:$F$501,0)),"") | AB36: =IFERROR(" ,"&INDEX($B$2:$B$501,MATCH($I36&AB$1,$F$2:$F$501,0)),"") | AC36: =IFERROR(" ,"&INDEX($B$2:$B$501,MATCH($I36&AC$1,$F$2:$F$501,0)),"") | AD36: =IFERROR(" ,"&INDEX($B$2:$B$501,MATCH($I36&AD$1,$F$2:$F$501,0)),"") | AE36: =IFERROR(" ,"&INDEX($B$2:$B$501,MATCH($I36&AE$1,$F$2:$F$501,0)),"") | AF36: =IFERROR(" ,"&INDEX($B$2:$B$501,MATCH($I36&AF$1,$F$2:$F$501,0)),"") | AV36: 35 | AW36: BETO | BM36: 35 | BN36: BETO | BO36: =VLOOKUP(BM36,A:B,2,0) -> BETO | BP36: =BO36=BN36 -> TRUE
A37: 36 | B37: ROGERINHO pg | C37: 2035158719 | D37: ok | E37: =COUNTIF($C$1:C37,C37) -> 1 | F37: =C37&E37 -> 20351587191 | G37: =IF(IFERROR(FIND("pg",LOWER(B37)),0)=0,0,1) -> 1 | H37: =IF(IFERROR(FIND("(f)",LOWER(B37)),0)=0,0,1) -> 0 | I37: 9144399667 | J37: =COUNTIF(C:C,I37) -> 2 | K37: =COUNTIFS(C:C,I37,G:G,1)+COUNTIFS(C:C,I37,H:H,1) -> 2 | L37: =CONCATENATE(P37,Q37,R37,S37,T37,U37,V37,) -> 53, 65 | M37: =CONCATENATE(Z37,AA37,AB37,AC37,AD37,AE37,AF37) -> ALAN KARLA pg ,ALAN KARLA pg | N37: =J37-K37 -> 0 | P37: =IFERROR(INDEX($A$2:$A$501,MATCH($I37&P$1,$F$2:$F$501,0)),"") -> 53 | Q37: =IFERROR(", "&INDEX($A$2:$A$501,MATCH($I37&Q$1,$F$2:$F$501,0)),"") -> , 65 | R37: =IFERROR(", "&INDEX($A$2:$A$501,MATCH($I37&R$1,$F$2:$F$501,0)),"") | S37: =IFERROR(", "&INDEX($A$2:$A$501,MATCH($I37&S$1,$F$2:$F$501,0)),"") | T37: =IFERROR(", "&INDEX($A$2:$A$501,MATCH($I37&T$1,$F$2:$F$501,0)),"") | U37: =IFERROR(", "&INDEX($A$2:$A$501,MATCH($I37&U$1,$F$2:$F$501,0)),"") | V37: =IFERROR(", "&INDEX($A$2:$A$501,MATCH($I37&V$1,$F$2:$F$501,0)),"") | Z37: =IFERROR(INDEX($B$2:$B$501,MATCH($I37&Z$1,$F$2:$F$501,0)),"") -> ALAN KARLA pg | AA37: =IFERROR(" ,"&INDEX($B$2:$B$501,MATCH($I37&AA$1,$F$2:$F$501,0)),"") -> ,ALAN KARLA pg | AB37: =IFERROR(" ,"&INDEX($B$2:$B$501,MATCH($I37&AB$1,$F$2:$F$501,0)),"") | AC37: =IFERROR(" ,"&INDEX($B$2:$B$501,MATCH($I37&AC$1,$F$2:$F$501,0)),"") | AD37: =IFERROR(" ,"&INDEX($B$2:$B$501,MATCH($I37&AD$1,$F$2:$F$501,0)),"") | AE37: =IFERROR(" ,"&INDEX($B$2:$B$501,MATCH($I37&AE$1,$F$2:$F$501,0)),"") | AF37: =IFERROR(" ,"&INDEX($B$2:$B$501,MATCH($I37&AF$1,$F$2:$F$501,0)),"") | AV37: 36 | AW37: ROGERINHO | BM37: 36 | BN37: ROGERINHO | BO37: =VLOOKUP(BM37,A:B,2,0) -> ROGERINHO pg | BP37: =BO37=BN37 -> FALSE
A38: 37 | B38: MARTINS | C38: 2039483635 | D38: ok | E38: =COUNTIF($C$1:C38,C38) -> 1 | F38: =C38&E38 -> 20394836351 | G38: =IF(IFERROR(FIND("pg",LOWER(B38)),0)=0,0,1) -> 0 | H38: =IF(IFERROR(FIND("(f)",LOWER(B38)),0)=0,0,1) -> 0 | I38: 2039237387 | J38: =COUNTIF(C:C,I38) -> 3 | K38: =COUNTIFS(C:C,I38,G:G,1)+COUNTIFS(C:C,I38,H:H,1) -> 3 | L38: =CONCATENATE(P38,Q38,R38,S38,T38,U38,V38,) -> 56, 126, 242 | M38: =CONCATENATE(Z38,AA38,AB38,AC38,AD38,AE38,AF38) -> LUCIANO Serjao pg ,LUCIANO Serjao pg ,LUCIANO Serjao pg | N38: =J38-K38 -> 0 | P38: =IFERROR(INDEX($A$2:$A$501,MATCH($I38&P$1,$F$2:$F$501,0)),"") -> 56 | Q38: =IFERROR(", "&INDEX($A$2:$A$501,MATCH($I38&Q$1,$F$2:$F$501,0)),"") -> , 126 | R38: =IFERROR(", "&INDEX($A$2:$A$501,MATCH($I38&R$1,$F$2:$F$501,0)),"") -> , 242 | S38: =IFERROR(", "&INDEX($A$2:$A$501,MATCH($I38&S$1,$F$2:$F$501,0)),"") | T38: =IFERROR(", "&INDEX($A$2:$A$501,MATCH($I38&T$1,$F$2:$F$501,0)),"") | U38: =IFERROR(", "&INDEX($A$2:$A$501,MATCH($I38&U$1,$F$2:$F$501,0)),"") | V38: =IFERROR(", "&INDEX($A$2:$A$501,MATCH($I38&V$1,$F$2:$F$501,0)),"") | Z38: =IFERROR(INDEX($B$2:$B$501,MATCH($I38&Z$1,$F$2:$F$501,0)),"") -> LUCIANO Serjao pg | AA38: =IFERROR(" ,"&INDEX($B$2:$B$501,MATCH($I38&AA$1,$F$2:$F$501,0)),"") -> ,LUCIANO Serjao pg | AB38: =IFERROR(" ,"&INDEX($B$2:$B$501,MATCH($I38&AB$1,$F$2:$F$501,0)),"") -> ,LUCIANO Serjao pg | AC38: =IFERROR(" ,"&INDEX($B$2:$B$501,MATCH($I38&AC$1,$F$2:$F$501,0)),"") | AD38: =IFERROR(" ,"&INDEX($B$2:$B$501,MATCH($I38&AD$1,$F$2:$F$501,0)),"") | AE38: =IFERROR(" ,"&INDEX($B$2:$B$501,MATCH($I38&AE$1,$F$2:$F$501,0)),"") | AF38: =IFERROR(" ,"&INDEX($B$2:$B$501,MATCH($I38&AF$1,$F$2:$F$501,0)),"") | AV38: 37 | AW38: MARTINS | BM38: 37 | BN38: MARTINS | BO38: =VLOOKUP(BM38,A:B,2,0) -> MARTINS | BP38: =BO38=BN38 -> TRUE
